Workbook
Name CABOffsetFromReleaseWD: Config!$B$8
Name CodeReviewCalendarDays: Config!$B$9
Name CodeReviewInviteCalendarDays: Config!$B$10
Name FileTypeList: Config!$G$3:$G$13
Name FrequencyList: Config!$H$3:$H$10
Name IAMList: Config!$I$3:$I$5
Name OUROffsetFromSR_WD: Config!$B$6
Name ReadyOffsetWD: Config!$B$4
Name RTSKOffsetFromOUR_WD: Config!$B$7
Name SprintCalendar: Sprints!$A$2:$C$12
Name SprintReadinessOffsetWD: Config!$B$15
Name SprintWarningDays: Config!$B$13
Name SprintWorkingDays: Config!$B$3
Name SROffsetFromStartWD: Config!$B$5
Name StatusList: Config!$E$3:$E$8
Name YesNoList: Config!$J$3:$J$4

Sheet Dashboard
B1: Application access & release tracker | I1: Formulas only. Update yellow cells on Tracker. Sheet is locked.
B2: As of | C2: =TODAY() -> 46255 | E2: KPIs use current Tracker columns (File Type Z / Frequency AF shared). TBD is separate from N/A. Reopen/recalc if numbers look stale.
B4: Applications | D4: Overdue tickets | F4: Blocked | I4: Due in 7 days | K4: In progress | M4: Fully ready | O4: overdue (days) | Q4: Raised on time
B5: =COUNTA(Tracker!A3:A100) -> 43 | D5: =SUMPRODUCT((Tracker!$A$3:$A$100<>"")*(Tracker!$S$3:$S$100<>"Completed")*(Tracker!$S$3:$S$100<>"N/A")*(ISNUMBER(Tracker!$Q$3:$Q$100))*(N(Tracker!$Q$3:$Q$100)<TODAY()))+SUMPRODUCT((Tracker!$A$3:$A$100<>"")*(Tracker!$V$3:$V$100<>"Completed")*(Tracker!$V$3:$V$100<>"N/A")*(ISNUMBER(Tracker!$T$3:$T$100))*(N(Tracker!$T$3:$T$100)<TODAY()))+SUMPRODUCT((Tracker!$A$3:$A$100<>"")*(Tracker!$Y$3:$Y$100<>"Completed")*(Tracker!$Y$3:$Y$100<>"N/A")*(ISNUMBER(Tracker!$W$3:$W$100))*(N(Tracker!$W$3:$W$100)<TODAY()))+SUMPRODUCT((Tracker!$A$3:$A$100<>"")*(Tracker!$AC$3:$AC$100<>"Completed")*(Tracker!$AC$3:$AC$100<>"N/A")*(ISNUMBER(Tracker!$AA$3:$AA$100))*(N(Tracker!$AA$3:$AA$100)<TODAY()))+SUMPRODUCT((Tracker!$A$3:$A$100<>"")*(Tracker!$AI$3:$AI$100<>"Completed")*(Tracker!$AI$3:$AI$100<>"N/A")*(ISNUMBER(Tracker!$AG$3:$AG$100))*(N(Tracker!$AG$3:$AG$100)<TODAY()))+SUMPRODUCT((Tracker!$A$3:$A$100<>"")*(Tracker!$AL$3:$AL$100<>"Completed")*(Tracker!$AL$3:$AL$100<>"N/A")*(ISNUMBER(Tracker!$AJ$3:$AJ$100))*(N(Tracker!$AJ$3:$AJ$100)<TODAY()))+SUMPRODUCT((Tracker!$A$3:$A$100<>"")*(Tracker!$AO$3:$AO$100<>"Completed")*(Tracker!$AO$3:$AO$100<>"N/A")*(ISNUMBER(Tracker!$AM$3:$AM$100))*(N(Tracker!$AM$3:$AM$100)<TODAY()))+SUMPRODUCT((Tracker!$A$3:$A$100<>"")*(Tracker!$AR$3:$AR$100<>"Completed")*(Tracker!$AR$3:$AR$100<>"N/A")*(ISNUMBER(Tracker!$AP$3:$AP$100))*(N(Tracker!$AP$3:$AP$100)<TODAY()))+SUMPRODUCT((Tracker!$A$3:$A$100<>"")*(Tracker!$AW$3:$AW$100<>"Completed")*(Tracker!$AW$3:$AW$100<>"N/A")*(ISNUMBER(Tracker!$AU$3:$AU$100))*(N(Tracker!$AU$3:$AU$100)<TODAY()))+SUMPRODUCT((Tracker!$A$3:$A$100<>"")*(Tracker!$AZ$3:$AZ$100<>"Completed")*(Tracker!$AZ$3:$AZ$100<>"N/A")*(ISNUMBER(Tracker!$AX$3:$AX$100))*(N(Tracker!$AX$3:$AX$100)<TODAY()))+SUMPRODUCT((Tracker!$A$3:$A$100<>"")*(Tracker!$BC$3:$BC$100<>"Completed")*(Tracker!$BC$3:$BC$100<>"N/A")*(ISNUMBER(Tracker!$BA$3:$BA$100))*(N(Tracker!$BA$3:$BA$100)<TODAY()))+SUMPRODUCT((Tracker!$A$3:$A$100<>"")*(Tracker!$BF$3:$BF$100<>"Completed")*(Tracker!$BF$3:$BF$100<>"N/A")*(ISNUMBER(Tracker!$BD$3:$BD$100))*(N(Tracker!$BD$3:$BD$100)<TODAY()))+SUMPRODUCT((Tracker!$A$3:$A$100<>"")*(Tracker!$P$3:$P$100<>"Completed")*(Tracker!$P$3:$P$100<>"N/A")*(ISNUMBER(Tracker!$O$3:$O$100))*(N(Tracker!$O$3:$O$100)<TODAY()))+SUMPRODUCT((Tracker!$A$3:$A$100<>"")*(Tracker!$BJ$3:$BJ$100<>"Completed")*(Tracker!$BJ$3:$BJ$100<>"N/A")*(ISNUMBER(Tracker!$BI$3:$BI$100))*(N(Tracker!$BI$3:$BI$100)<TODAY()))+SUMPRODUCT((Tracker!$A$3:$A$100<>"")*(Tracker!$BL$3:$BL$100<>"Completed")*(Tracker!$BL$3:$BL$100<>"N/A")*(ISNUMBER(Tracker!$BK$3:$BK$100))*(N(Tracker!$BK$3:$BK$100)<TODAY()))+SUMPRODUCT((Tracker!$A$3:$A$100<>"")*(Tracker!$BN$3:$BN$100<>"Completed")*(Tracker!$BN$3:$BN$100<>"N/A")*(ISNUMBER(Tracker!$BM$3:$BM$100))*(N(Tracker!$BM$3:$BM$100)<TODAY())) -> 205 | F5: =SUMPRODUCT((Tracker!$A$3:$A$100<>"")*(ISNUMBER(Tracker!$Q$3:$Q$100))*(Tracker!$S$3:$S$100="Blocked"))+SUMPRODUCT((Tracker!$A$3:$A$100<>"")*(ISNUMBER(Tracker!$T$3:$T$100))*(Tracker!$V$3:$V$100="Blocked"))+SUMPRODUCT((Tracker!$A$3:$A$100<>"")*(ISNUMBER(Tracker!$W$3:$W$100))*(Tracker!$Y$3:$Y$100="Blocked"))+SUMPRODUCT((Tracker!$A$3:$A$100<>"")*(ISNUMBER(Tracker!$AA$3:$AA$100))*(Tracker!$AC$3:$AC$100="Blocked"))+SUMPRODUCT((Tracker!$A$3:$A$100<>"")*(ISNUMBER(Tracker!$AG$3:$AG$100))*(Tracker!$AI$3:$AI$100="Blocked"))+SUMPRODUCT((Tracker!$A$3:$A$100<>"")*(ISNUMBER(Tracker!$AJ$3:$AJ$100))*(Tracker!$AL$3:$AL$100="Blocked"))+SUMPRODUCT((Tracker!$A$3:$A$100<>"")*(ISNUMBER(Tracker!$AM$3:$AM$100))*(Tracker!$AO$3:$AO$100="Blocked"))+SUMPRODUCT((Tracker!$A$3:$A$100<>"")*(ISNUMBER(Tracker!$AP$3:$AP$100))*(Tracker!$AR$3:$AR$100="Blocked"))+SUMPRODUCT((Tracker!$A$3:$A$100<>"")*(ISNUMBER(Tracker!$AU$3:$AU$100))*(Tracker!$AW$3:$AW$100="Blocked"))+SUMPRODUCT((Tracker!$A$3:$A$100<>"")*(ISNUMBER(Tracker!$AX$3:$AX$100))*(Tracker!$AZ$3:$AZ$100="Blocked"))+SUMPRODUCT((Tracker!$A$3:$A$100<>"")*(ISNUMBER(Tracker!$BA$3:$BA$100))*(Tracker!$BC$3:$BC$100="Blocked"))+SUMPRODUCT((Tracker!$A$3:$A$100<>"")*(ISNUMBER(Tracker!$BD$3:$BD$100))*(Tracker!$BF$3:$BF$100="Blocked"))+SUMPRODUCT((Tracker!$A$3:$A$100<>"")*(ISNUMBER(Tracker!$O$3:$O$100))*(Tracker!$P$3:$P$100="Blocked"))+SUMPRODUCT((Tracker!$A$3:$A$100<>"")*(ISNUMBER(Tracker!$BI$3:$BI$100))*(Tracker!$BJ$3:$BJ$100="Blocked"))+SUMPRODUCT((Tracker!$A$3:$A$100<>"")*(ISNUMBER(Tracker!$BK$3:$BK$100))*(Tracker!$BL$3:$BL$100="Blocked"))+SUMPRODUCT((Tracker!$A$3:$A$100<>"")*(ISNUMBER(Tracker!$BM$3:$BM$100))*(Tracker!$BN$3:$BN$100="Blocked")) -> 0 | I5: =SUMPRODUCT((Tracker!$A$3:$A$100<>"")*(Tracker!$S$3:$S$100<>"Completed")*(Tracker!$S$3:$S$100<>"N/A")*(ISNUMBER(Tracker!$Q$3:$Q$100))*(N(Tracker!$Q$3:$Q$100)>=TODAY())*(N(Tracker!$Q$3:$Q$100)<=TODAY()+7))+SUMPRODUCT((Tracker!$A$3:$A$100<>"")*(Tracker!$V$3:$V$100<>"Completed")*(Tracker!$V$3:$V$100<>"N/A")*(ISNUMBER(Tracker!$T$3:$T$100))*(N(Tracker!$T$3:$T$100)>=TODAY())*(N(Tracker!$T$3:$T$100)<=TODAY()+7))+SUMPRODUCT((Tracker!$A$3:$A$100<>"")*(Tracker!$Y$3:$Y$100<>"Completed")*(Tracker!$Y$3:$Y$100<>"N/A")*(ISNUMBER(Tracker!$W$3:$W$100))*(N(Tracker!$W$3:$W$100)>=TODAY())*(N(Tracker!$W$3:$W$100)<=TODAY()+7))+SUMPRODUCT((Tracker!$A$3:$A$100<>"")*(Tracker!$AC$3:$AC$100<>"Completed")*(Tracker!$AC$3:$AC$100<>"N/A")*(ISNUMBER(Tracker!$AA$3:$AA$100))*(N(Tracker!$AA$3:$AA$100)>=TODAY())*(N(Tracker!$AA$3:$AA$100)<=TODAY()+7))+SUMPRODUCT((Tracker!$A$3:$A$100<>"")*(Tracker!$AI$3:$AI$100<>"Completed")*(Tracker!$AI$3:$AI$100<>"N/A")*(ISNUMBER(Tracker!$AG$3:$AG$100))*(N(Tracker!$AG$3:$AG$100)>=TODAY())*(N(Tracker!$AG$3:$AG$100)<=TODAY()+7))+SUMPRODUCT((Tracker!$A$3:$A$100<>"")*(Tracker!$AL$3:$AL$100<>"Completed")*(Tracker!$AL$3:$AL$100<>"N/A")*(ISNUMBER(Tracker!$AJ$3:$AJ$100))*(N(Tracker!$AJ$3:$AJ$100)>=TODAY())*(N(Tracker!$AJ$3:$AJ$100)<=TODAY()+7))+SUMPRODUCT((Tracker!$A$3:$A$100<>"")*(Tracker!$AO$3:$AO$100<>"Completed")*(Tracker!$AO$3:$AO$100<>"N/A")*(ISNUMBER(Tracker!$AM$3:$AM$100))*(N(Tracker!$AM$3:$AM$100)>=TODAY())*(N(Tracker!$AM$3:$AM$100)<=TODAY()+7))+SUMPRODUCT((Tracker!$A$3:$A$100<>"")*(Tracker!$AR$3:$AR$100<>"Completed")*(Tracker!$AR$3:$AR$100<>"N/A")*(ISNUMBER(Tracker!$AP$3:$AP$100))*(N(Tracker!$AP$3:$AP$100)>=TODAY())*(N(Tracker!$AP$3:$AP$100)<=TODAY()+7))+SUMPRODUCT((Tracker!$A$3:$A$100<>"")*(Tracker!$AW$3:$AW$100<>"Completed")*(Tracker!$AW$3:$AW$100<>"N/A")*(ISNUMBER(Tracker!$AU$3:$AU$100))*(N(Tracker!$AU$3:$AU$100)>=TODAY())*(N(Tracker!$AU$3:$AU$100)<=TODAY()+7))+SUMPRODUCT((Tracker!$A$3:$A$100<>"")*(Tracker!$AZ$3:$AZ$100<>"Completed")*(Tracker!$AZ$3:$AZ$100<>"N/A")*(ISNUMBER(Tracker!$AX$3:$AX$100))*(N(Tracker!$AX$3:$AX$100)>=TODAY())*(N(Tracker!$AX$3:$AX$100)<=TODAY()+7))+SUMPRODUCT((Tracker!$A$3:$A$100<>"")*(Tracker!$BC$3:$BC$100<>"Completed")*(Tracker!$BC$3:$BC$100<>"N/A")*(ISNUMBER(Tracker!$BA$3:$BA$100))*(N(Tracker!$BA$3:$BA$100)>=TODAY())*(N(Tracker!$BA$3:$BA$100)<=TODAY()+7))+SUMPRODUCT((Tracker!$A$3:$A$100<>"")*(Tracker!$BF$3:$BF$100<>"Completed")*(Tracker!$BF$3:$BF$100<>"N/A")*(ISNUMBER(Tracker!$BD$3:$BD$100))*(N(Tracker!$BD$3:$BD$100)>=TODAY())*(N(Tracker!$BD$3:$BD$100)<=TODAY()+7))+SUMPRODUCT((Tracker!$A$3:$A$100<>"")*(Tracker!$P$3:$P$100<>"Completed")*(Tracker!$P$3:$P$100<>"N/A")*(ISNUMBER(Tracker!$O$3:$O$100))*(N(Tracker!$O$3:$O$100)>=TODAY())*(N(Tracker!$O$3:$O$100)<=TODAY()+7))+SUMPRODUCT((Tracker!$A$3:$A$100<>"")*(Tracker!$BJ$3:$BJ$100<>"Completed")*(Tracker!$BJ$3:$BJ$100<>"N/A")*(ISNUMBER(Tracker!$BI$3:$BI$100))*(N(Tracker!$BI$3:$BI$100)>=TODAY())*(N(Tracker!$BI$3:$BI$100)<=TODAY()+7))+SUMPRODUCT((Tracker!$A$3:$A$100<>"")*(Tracker!$BL$3:$BL$100<>"Completed")*(Tracker!$BL$3:$BL$100<>"N/A")*(ISNUMBER(Tracker!$BK$3:$BK$100))*(N(Tracker!$BK$3:$BK$100)>=TODAY())*(N(Tracker!$BK$3:$BK$100)<=TODAY()+7))+SUMPRODUCT((Tracker!$A$3:$A$100<>"")*(Tracker!$BN$3:$BN$100<>"Completed")*(Tracker!$BN$3:$BN$100<>"N/A")*(ISNUMBER(Tracker!$BM$3:$BM$100))*(N(Tracker!$BM$3:$BM$100)>=TODAY())*(N(Tracker!$BM$3:$BM$100)<=TODAY()+7)) -> 0 | K5: =SUMPRODUCT((Tracker!$A$3:$A$100<>"")*(ISNUMBER(Tracker!$Q$3:$Q$100))*(Tracker!$S$3:$S$100="In Progress"))+SUMPRODUCT((Tracker!$A$3:$A$100<>"")*(ISNUMBER(Tracker!$T$3:$T$100))*(Tracker!$V$3:$V$100="In Progress"))+SUMPRODUCT((Tracker!$A$3:$A$100<>"")*(ISNUMBER(Tracker!$W$3:$W$100))*(Tracker!$Y$3:$Y$100="In Progress"))+SUMPRODUCT((Tracker!$A$3:$A$100<>"")*(ISNUMBER(Tracker!$AA$3:$AA$100))*(Tracker!$AC$3:$AC$100="In Progress"))+SUMPRODUCT((Tracker!$A$3:$A$100<>"")*(ISNUMBER(Tracker!$AG$3:$AG$100))*(Tracker!$AI$3:$AI$100="In Progress"))+SUMPRODUCT((Tracker!$A$3:$A$100<>"")*(ISNUMBER(Tracker!$AJ$3:$AJ$100))*(Tracker!$AL$3:$AL$100="In Progress"))+SUMPRODUCT((Tracker!$A$3:$A$100<>"")*(ISNUMBER(Tracker!$AM$3:$AM$100))*(Tracker!$AO$3:$AO$100="In Progress"))+SUMPRODUCT((Tracker!$A$3:$A$100<>"")*(ISNUMBER(Tracker!$AP$3:$AP$100))*(Tracker!$AR$3:$AR$100="In Progress"))+SUMPRODUCT((Tracker!$A$3:$A$100<>"")*(ISNUMBER(Tracker!$AU$3:$AU$100))*(Tracker!$AW$3:$AW$100="In Progress"))+SUMPRODUCT((Tracker!$A$3:$A$100<>"")*(ISNUMBER(Tracker!$AX$3:$AX$100))*(Tracker!$AZ$3:$AZ$100="In Progress"))+SUMPRODUCT((Tracker!$A$3:$A$100<>"")*(ISNUMBER(Tracker!$BA$3:$BA$100))*(Tracker!$BC$3:$BC$100="In Progress"))+SUMPRODUCT((Tracker!$A$3:$A$100<>"")*(ISNUMBER(Tracker!$BD$3:$BD$100))*(Tracker!$BF$3:$BF$100="In Progress"))+SUMPRODUCT((Tracker!$A$3:$A$100<>"")*(ISNUMBER(Tracker!$O$3:$O$100))*(Tracker!$P$3:$P$100="In Progress"))+SUMPRODUCT((Tracker!$A$3:$A$100<>"")*(ISNUMBER(Tracker!$BI$3:$BI$100))*(Tracker!$BJ$3:$BJ$100="In Progress"))+SUMPRODUCT((Tracker!$A$3:$A$100<>"")*(ISNUMBER(Tracker!$BK$3:$BK$100))*(Tracker!$BL$3:$BL$100="In Progress"))+SUMPRODUCT((Tracker!$A$3:$A$100<>"")*(ISNUMBER(Tracker!$BM$3:$BM$100))*(Tracker!$BN$3:$BN$100="In Progress")) -> 24 | M5: =COUNTIF(Tracker!D3:D100,"Completed") -> 0 | O5: =IFERROR(MAX(Tracker!G3:G100),0) -> 35 | Q5: =SUMPRODUCT((Tracker!$A$3:$A$100<>"")*(ISNUMBER(Tracker!$Q$3:$Q$100))*(ISNUMBER(Tracker!$R$3:$R$100))*(N(Tracker!$R$3:$R$100)<=N(Tracker!$Q$3:$Q$100)))+SUMPRODUCT((Tracker!$A$3:$A$100<>"")*(ISNUMBER(Tracker!$T$3:$T$100))*(ISNUMBER(Tracker!$U$3:$U$100))*(N(Tracker!$U$3:$U$100)<=N(Tracker!$T$3:$T$100)))+SUMPRODUCT((Tracker!$A$3:$A$100<>"")*(ISNUMBER(Tracker!$W$3:$W$100))*(ISNUMBER(Tracker!$X$3:$X$100))*(N(Tracker!$X$3:$X$100)<=N(Tracker!$W$3:$W$100)))+SUMPRODUCT((Tracker!$A$3:$A$100<>"")*(ISNUMBER(Tracker!$AA$3:$AA$100))*(ISNUMBER(Tracker!$AB$3:$AB$100))*(N(Tracker!$AB$3:$AB$100)<=N(Tracker!$AA$3:$AA$100)))+SUMPRODUCT((Tracker!$A$3:$A$100<>"")*(ISNUMBER(Tracker!$AG$3:$AG$100))*(ISNUMBER(Tracker!$AH$3:$AH$100))*(N(Tracker!$AH$3:$AH$100)<=N(Tracker!$AG$3:$AG$100)))+SUMPRODUCT((Tracker!$A$3:$A$100<>"")*(ISNUMBER(Tracker!$AJ$3:$AJ$100))*(ISNUMBER(Tracker!$AK$3:$AK$100))*(N(Tracker!$AK$3:$AK$100)<=N(Tracker!$AJ$3:$AJ$100)))+SUMPRODUCT((Tracker!$A$3:$A$100<>"")*(ISNUMBER(Tracker!$AM$3:$AM$100))*(ISNUMBER(Tracker!$AN$3:$AN$100))*(N(Tracker!$AN$3:$AN$100)<=N(Tracker!$AM$3:$AM$100)))+SUMPRODUCT((Tracker!$A$3:$A$100<>"")*(ISNUMBER(Tracker!$AQ$3:$AQ$100))*(ISNUMBER(Tracker!$AR$3:$AR$100))*(N(Tracker!$AR$3:$AR$100)<=N(Tracker!$AQ$3:$AQ$100)))+SUMPRODUCT((Tracker!$A$3:$A$100<>"")*(ISNUMBER(Tracker!$AW$3:$AW$100))*(ISNUMBER(Tracker!$AX$3:$AX$100))*(N(Tracker!$AX$3:$AX$100)<=N(Tracker!$AW$3:$AW$100)))+SUMPRODUCT((Tracker!$A$3:$A$100<>"")*(ISNUMBER(Tracker!$AZ$3:$AZ$100))*(ISNUMBER(Tracker!$BA$3:$BA$100))*(N(Tracker!$BA$3:$BA$100)<=N(Tracker!$AZ$3:$AZ$100)))+SUMPRODUCT((Tracker!$A$3:$A$100<>"")*(ISNUMBER(Tracker!$BC$3:$BC$100))*(ISNUMBER(Tracker!$BD$3:$BD$100))*(N(Tracker!$BD$3:$BD$100)<=N(Tracker!$BC$3:$BC$100)))+SUMPRODUCT((Tracker!$A$3:$A$100<>"")*(ISNUMBER(Tracker!$BG$3:$BG$100))*(ISNUMBER(Tracker!$BH$3:$BH$100))*(N(Tracker!$BH$3:$BH$100)<=N(Tracker!$BG$3:$BG$100))) -> 100
B6: Apps with a name filled | D6: Date in the past and status not Completed | F6: Requests marked Blocked | I6: Raise-by in the next week, not Completed | K6: Tickets marked In Progress | M6: Every dated request Completed | O6: Days past raise-by among open requests. Increases daily until Completed. | Q6: Requests with Raised On filled on or before the raise-by date.
B8: Apps overdue - worst first (days overdue keeps increasing until Completed) | I8: Where work is stuck - by request type
B9: Application | C9: Sprint | D9: Overall Status | E9: Next Action | F9: Next Action Date | G9: Days overdue | I9: Request type | J9: Overdue | K9: Due in 7 days | L9: Blocked | M9: In Progress | N9: Pending | O9: Completed | P9: Overdue bar
B10: =IFERROR(INDEX(Tracker!$A$3:$A$100, MATCH(_xlfn.SINGLE(_xlfn.AGGREGATE(15, 6, Tracker!$CG$3:$CG$100, 1)), Tracker!$CG$3:$CG$100, 0)), "") -> Ecosys | C10: =IF(B10 = "", "", IFERROR(INDEX(Tracker!$C$3:$C$100, MATCH(_xlfn.SINGLE(_xlfn.AGGREGATE(15, 6, Tracker!$CG$3:$CG$100, 1)), Tracker!$CG$3:$CG$100, 0)), "")) -> Sprint 17 | D10: =IF(B10 = "", "", IFERROR(INDEX(Tracker!$D$3:$D$100, MATCH(_xlfn.SINGLE(_xlfn.AGGREGATE(15, 6, Tracker!$CG$3:$CG$100, 1)), Tracker!$CG$3:$CG$100, 0)), "")) -> In Progress | E10: =IF(B10 = "", "", IFERROR(INDEX(Tracker!$E$3:$E$100, MATCH(_xlfn.SINGLE(_xlfn.AGGREGATE(15, 6, Tracker!$CG$3:$CG$100, 1)), Tracker!$CG$3:$CG$100, 0)), "")) -> Dev File R-Task | F10: =IF(B10 = "", "", IFERROR(INDEX(Tracker!$F$3:$F$100, MATCH(_xlfn.SINGLE(_xlfn.AGGREGATE(15, 6, Tracker!$CG$3:$CG$100, 1)), Tracker!$CG$3:$CG$100, 0)), "")) -> 46220 | G10: =IF(B10 = "", "", IFERROR(INDEX(Tracker!$G$3:$G$100, MATCH(_xlfn.SINGLE(_xlfn.AGGREGATE(15, 6, Tracker!$CG$3:$CG$100, 1)), Tracker!$CG$3:$CG$100, 0)), "")) -> 35 | I10: Dev R-Task | J10: =SUMPRODUCT((Tracker!$A$3:$A$100<>"")*(Tracker!$S$3:$S$100<>"Completed")*(Tracker!$S$3:$S$100<>"N/A")*(ISNUMBER(Tracker!$Q$3:$Q$100))*(N(Tracker!$Q$3:$Q$100)<TODAY())) -> 10 | K10: =SUMPRODUCT((Tracker!$A$3:$A$100<>"")*(Tracker!$S$3:$S$100<>"Completed")*(Tracker!$S$3:$S$100<>"N/A")*(ISNUMBER(Tracker!$Q$3:$Q$100))*(N(Tracker!$Q$3:$Q$100)>=TODAY())*(N(Tracker!$Q$3:$Q$100)<=TODAY()+7)) -> 0 | L10: =SUMPRODUCT((Tracker!$A$3:$A$100<>"")*(ISNUMBER(Tracker!$Q$3:$Q$100))*(Tracker!$S$3:$S$100="Blocked")) -> 0 | M10: =SUMPRODUCT((Tracker!$A$3:$A$100<>"")*(ISNUMBER(Tracker!$Q$3:$Q$100))*(Tracker!$S$3:$S$100="In Progress")) -> 0 | N10: =SUMPRODUCT((Tracker!$A$3:$A$100<>"")*(ISNUMBER(Tracker!$M$3:$M$100))*(Tracker!$N$3:$N$100<>"Completed")*(Tracker!$N$3:$N$100<>"Blocked")*(Tracker!$N$3:$N$100<>"In Progress")) -> 43 | O10: =SUMPRODUCT((Tracker!$A$3:$A$100<>"")*(ISNUMBER(Tracker!$M$3:$M$100))*(Tracker!$N$3:$N$100="Completed")) -> 0 | P10: =IF(N(J10)<=0,"",REPT("|",MIN(N(J10),25))) -> ||||||||||
B11: =IFERROR(INDEX(Tracker!$A$3:$A$100, MATCH(_xlfn.SINGLE(_xlfn.AGGREGATE(15, 6, Tracker!$CG$3:$CG$100, 2)), Tracker!$CG$3:$CG$100, 0)), "") -> ALLOCATIONS | C11: =IF(B11 = "", "", IFERROR(INDEX(Tracker!$C$3:$C$100, MATCH(_xlfn.SINGLE(_xlfn.AGGREGATE(15, 6, Tracker!$CG$3:$CG$100, 2)), Tracker!$CG$3:$CG$100, 0)), "")) -> Sprint 17 | D11: =IF(B11 = "", "", IFERROR(INDEX(Tracker!$D$3:$D$100, MATCH(_xlfn.SINGLE(_xlfn.AGGREGATE(15, 6, Tracker!$CG$3:$CG$100, 2)), Tracker!$CG$3:$CG$100, 0)), "")) -> In Progress | E11: =IF(B11 = "", "", IFERROR(INDEX(Tracker!$E$3:$E$100, MATCH(_xlfn.SINGLE(_xlfn.AGGREGATE(15, 6, Tracker!$CG$3:$CG$100, 2)), Tracker!$CG$3:$CG$100, 0)), "")) -> Dev R-Task | F11: =IF(B11 = "", "", IFERROR(INDEX(Tracker!$F$3:$F$100, MATCH(_xlfn.SINGLE(_xlfn.AGGREGATE(15, 6, Tracker!$CG$3:$CG$100, 2)), Tracker!$CG$3:$CG$100, 0)), "")) -> 46220 | G11: =IF(B11 = "", "", IFERROR(INDEX(Tracker!$G$3:$G$100, MATCH(_xlfn.SINGLE(_xlfn.AGGREGATE(15, 6, Tracker!$CG$3:$CG$100, 2)), Tracker!$CG$3:$CG$100, 0)), "")) -> 35 | I11: Dev OUR | J11: =SUMPRODUCT((Tracker!$A$3:$A$100<>"")*(Tracker!$V$3:$V$100<>"Completed")*(Tracker!$V$3:$V$100<>"N/A")*(ISNUMBER(Tracker!$T$3:$T$100))*(N(Tracker!$T$3:$T$100)<TODAY())) -> 10 | K11: =SUMPRODUCT((Tracker!$A$3:$A$100<>"")*(Tracker!$V$3:$V$100<>"Completed")*(Tracker!$V$3:$V$100<>"N/A")*(ISNUMBER(Tracker!$T$3:$T$100))*(N(Tracker!$T$3:$T$100)>=TODAY())*(N(Tracker!$T$3:$T$100)<=TODAY()+7)) -> 0 | L11: =SUMPRODUCT((Tracker!$A$3:$A$100<>"")*(ISNUMBER(Tracker!$T$3:$T$100))*(Tracker!$V$3:$V$100="Blocked")) -> 0 | M11: =SUMPRODUCT((Tracker!$A$3:$A$100<>"")*(ISNUMBER(Tracker!$T$3:$T$100))*(Tracker!$V$3:$V$100="In Progress")) -> 0 | N11: =SUMPRODUCT((Tracker!$A$3:$A$100<>"")*(ISNUMBER(Tracker!$O$3:$O$100))*(Tracker!$P$3:$P$100<>"Completed")*(Tracker!$P$3:$P$100<>"Blocked")*(Tracker!$P$3:$P$100<>"In Progress")) -> 14 | O11: =SUMPRODUCT((Tracker!$A$3:$A$100<>"")*(ISNUMBER(Tracker!$O$3:$O$100))*(Tracker!$P$3:$P$100="Completed")) -> 7 | P11: =IF(N(J11)<=0,"",REPT("|",MIN(N(J11),25))) -> ||||||||||
B12: =IFERROR(INDEX(Tracker!$A$3:$A$100, MATCH(_xlfn.SINGLE(_xlfn.AGGREGATE(15, 6, Tracker!$CG$3:$CG$100, 3)), Tracker!$CG$3:$CG$100, 0)), "") -> AUDIT REPORTS | C12: =IF(B12 = "", "", IFERROR(INDEX(Tracker!$C$3:$C$100, MATCH(_xlfn.SINGLE(_xlfn.AGGREGATE(15, 6, Tracker!$CG$3:$CG$100, 3)), Tracker!$CG$3:$CG$100, 0)), "")) -> Sprint 17 | D12: =IF(B12 = "", "", IFERROR(INDEX(Tracker!$D$3:$D$100, MATCH(_xlfn.SINGLE(_xlfn.AGGREGATE(15, 6, Tracker!$CG$3:$CG$100, 3)), Tracker!$CG$3:$CG$100, 0)), "")) -> In Progress | E12: =IF(B12 = "", "", IFERROR(INDEX(Tracker!$E$3:$E$100, MATCH(_xlfn.SINGLE(_xlfn.AGGREGATE(15, 6, Tracker!$CG$3:$CG$100, 3)), Tracker!$CG$3:$CG$100, 0)), "")) -> Prod OUR | F12: =IF(B12 = "", "", IFERROR(INDEX(Tracker!$F$3:$F$100, MATCH(_xlfn.SINGLE(_xlfn.AGGREGATE(15, 6, Tracker!$CG$3:$CG$100, 3)), Tracker!$CG$3:$CG$100, 0)), "")) -> 46224 | G12: =IF(B12 = "", "", IFERROR(INDEX(Tracker!$G$3:$G$100, MATCH(_xlfn.SINGLE(_xlfn.AGGREGATE(15, 6, Tracker!$CG$3:$CG$100, 3)), Tracker!$CG$3:$CG$100, 0)), "")) -> 31 | I12: Dev Service Request | J12: =SUMPRODUCT((Tracker!$A$3:$A$100<>"")*(Tracker!$Y$3:$Y$100<>"Completed")*(Tracker!$Y$3:$Y$100<>"N/A")*(ISNUMBER(Tracker!$W$3:$W$100))*(N(Tracker!$W$3:$W$100)<TODAY())) -> 11 | K12: =SUMPRODUCT((Tracker!$A$3:$A$100<>"")*(Tracker!$Y$3:$Y$100<>"Completed")*(Tracker!$Y$3:$Y$100<>"N/A")*(ISNUMBER(Tracker!$W$3:$W$100))*(N(Tracker!$W$3:$W$100)>=TODAY())*(N(Tracker!$W$3:$W$100)<=TODAY()+7)) -> 0 | L12: =SUMPRODUCT((Tracker!$A$3:$A$100<>"")*(ISNUMBER(Tracker!$W$3:$W$100))*(Tracker!$Y$3:$Y$100="Blocked")) -> 0 | M12: =SUMPRODUCT((Tracker!$A$3:$A$100<>"")*(ISNUMBER(Tracker!$W$3:$W$100))*(Tracker!$Y$3:$Y$100="In Progress")) -> 1 | N12: =SUMPRODUCT((Tracker!$A$3:$A$100<>"")*(ISNUMBER(Tracker!$Q$3:$Q$100))*(Tracker!$R$3:$R$100<>"Completed")*(Tracker!$R$3:$R$100<>"Blocked")*(Tracker!$R$3:$R$100<>"In Progress")) -> 43 | O12: =SUMPRODUCT((Tracker!$A$3:$A$100<>"")*(ISNUMBER(Tracker!$Q$3:$Q$100))*(Tracker!$R$3:$R$100="Completed")) -> 0 | P12: =IF(N(J12)<=0,"",REPT("|",MIN(N(J12),25))) -> |||||||||||
B13: =IFERROR(INDEX(Tracker!$A$3:$A$100, MATCH(_xlfn.SINGLE(_xlfn.AGGREGATE(15, 6, Tracker!$CG$3:$CG$100, 4)), Tracker!$CG$3:$CG$100, 0)), "") -> EDDS | C13: =IF(B13 = "", "", IFERROR(INDEX(Tracker!$C$3:$C$100, MATCH(_xlfn.SINGLE(_xlfn.AGGREGATE(15, 6, Tracker!$CG$3:$CG$100, 4)), Tracker!$CG$3:$CG$100, 0)), "")) -> Sprint 17 | D13: =IF(B13 = "", "", IFERROR(INDEX(Tracker!$D$3:$D$100, MATCH(_xlfn.SINGLE(_xlfn.AGGREGATE(15, 6, Tracker!$CG$3:$CG$100, 4)), Tracker!$CG$3:$CG$100, 0)), "")) -> In Progress | E13: =IF(B13 = "", "", IFERROR(INDEX(Tracker!$E$3:$E$100, MATCH(_xlfn.SINGLE(_xlfn.AGGREGATE(15, 6, Tracker!$CG$3:$CG$100, 4)), Tracker!$CG$3:$CG$100, 0)), "")) -> Prod OUR | F13: =IF(B13 = "", "", IFERROR(INDEX(Tracker!$F$3:$F$100, MATCH(_xlfn.SINGLE(_xlfn.AGGREGATE(15, 6, Tracker!$CG$3:$CG$100, 4)), Tracker!$CG$3:$CG$100, 0)), "")) -> 46224 | G13: =IF(B13 = "", "", IFERROR(INDEX(Tracker!$G$3:$G$100, MATCH(_xlfn.SINGLE(_xlfn.AGGREGATE(15, 6, Tracker!$CG$3:$CG$100, 4)), Tracker!$CG$3:$CG$100, 0)), "")) -> 31 | I13: Dev File R-Task | J13: =SUMPRODUCT((Tracker!$A$3:$A$100<>"")*(Tracker!$AC$3:$AC$100<>"Completed")*(Tracker!$AC$3:$AC$100<>"N/A")*(ISNUMBER(Tracker!$AA$3:$AA$100))*(N(Tracker!$AA$3:$AA$100)<TODAY())) -> 4 | K13: =SUMPRODUCT((Tracker!$A$3:$A$100<>"")*(Tracker!$AC$3:$AC$100<>"Completed")*(Tracker!$AC$3:$AC$100<>"N/A")*(ISNUMBER(Tracker!$AA$3:$AA$100))*(N(Tracker!$AA$3:$AA$100)>=TODAY())*(N(Tracker!$AA$3:$AA$100)<=TODAY()+7)) -> 0 | L13: =SUMPRODUCT((Tracker!$A$3:$A$100<>"")*(ISNUMBER(Tracker!$AA$3:$AA$100))*(Tracker!$AC$3:$AC$100="Blocked")) -> 0 | M13: =SUMPRODUCT((Tracker!$A$3:$A$100<>"")*(ISNUMBER(Tracker!$AG$3:$AG$100))*(Tracker!$AI$3:$AI$100="In Progress")) -> 1 | N13: =SUMPRODUCT((Tracker!$A$3:$A$100<>"")*(ISNUMBER(Tracker!$S$3:$S$100))*(Tracker!$T$3:$T$100<>"Completed")*(Tracker!$T$3:$T$100<>"Blocked")*(Tracker!$T$3:$T$100<>"In Progress")) -> 0 | O13: =SUMPRODUCT((Tracker!$A$3:$A$100<>"")*(ISNUMBER(Tracker!$S$3:$S$100))*(Tracker!$T$3:$T$100="Completed")) -> 0 | P13: =IF(N(J13)<=0,"",REPT("|",MIN(N(J13),25))) -> ||||
B14: =IFERROR(INDEX(Tracker!$A$3:$A$100, MATCH(_xlfn.SINGLE(_xlfn.AGGREGATE(15, 6, Tracker!$CG$3:$CG$100, 5)), Tracker!$CG$3:$CG$100, 0)), "") -> EPM_BALANCES | C14: =IF(B14 = "", "", IFERROR(INDEX(Tracker!$C$3:$C$100, MATCH(_xlfn.SINGLE(_xlfn.AGGREGATE(15, 6, Tracker!$CG$3:$CG$100, 5)), Tracker!$CG$3:$CG$100, 0)), "")) -> Sprint 17 | D14: =IF(B14 = "", "", IFERROR(INDEX(Tracker!$D$3:$D$100, MATCH(_xlfn.SINGLE(_xlfn.AGGREGATE(15, 6, Tracker!$CG$3:$CG$100, 5)), Tracker!$CG$3:$CG$100, 0)), "")) -> In Progress | E14: =IF(B14 = "", "", IFERROR(INDEX(Tracker!$E$3:$E$100, MATCH(_xlfn.SINGLE(_xlfn.AGGREGATE(15, 6, Tracker!$CG$3:$CG$100, 5)), Tracker!$CG$3:$CG$100, 0)), "")) -> Prod OUR | F14: =IF(B14 = "", "", IFERROR(INDEX(Tracker!$F$3:$F$100, MATCH(_xlfn.SINGLE(_xlfn.AGGREGATE(15, 6, Tracker!$CG$3:$CG$100, 5)), Tracker!$CG$3:$CG$100, 0)), "")) -> 46224 | G14: =IF(B14 = "", "", IFERROR(INDEX(Tracker!$G$3:$G$100, MATCH(_xlfn.SINGLE(_xlfn.AGGREGATE(15, 6, Tracker!$CG$3:$CG$100, 5)), Tracker!$CG$3:$CG$100, 0)), "")) -> 31 | I14: QA R-Task | J14: =SUMPRODUCT((Tracker!$A$3:$A$100<>"")*(Tracker!$AI$3:$AI$100<>"Completed")*(Tracker!$AI$3:$AI$100<>"N/A")*(ISNUMBER(Tracker!$AG$3:$AG$100))*(N(Tracker!$AG$3:$AG$100)<TODAY())) -> 10 | K14: =SUMPRODUCT((Tracker!$A$3:$A$100<>"")*(Tracker!$AI$3:$AI$100<>"Completed")*(Tracker!$AI$3:$AI$100<>"N/A")*(ISNUMBER(Tracker!$AG$3:$AG$100))*(N(Tracker!$AG$3:$AG$100)>=TODAY())*(N(Tracker!$AG$3:$AG$100)<=TODAY()+7)) -> 0 | L14: =SUMPRODUCT((Tracker!$A$3:$A$100<>"")*(ISNUMBER(Tracker!$AG$3:$AG$100))*(Tracker!$AI$3:$AI$100="Blocked")) -> 0 | M14: =SUMPRODUCT((Tracker!$A$3:$A$100<>"")*(ISNUMBER(Tracker!$AJ$3:$AJ$100))*(Tracker!$AL$3:$AL$100="In Progress")) -> 0 | N14: =SUMPRODUCT((Tracker!$A$3:$A$100<>"")*(ISNUMBER(Tracker!$U$3:$U$100))*(Tracker!$V$3:$V$100<>"Completed")*(Tracker!$V$3:$V$100<>"Blocked")*(Tracker!$V$3:$V$100<>"In Progress")) -> 0 | O14: =SUMPRODUCT((Tracker!$A$3:$A$100<>"")*(ISNUMBER(Tracker!$U$3:$U$100))*(Tracker!$V$3:$V$100="Completed")) -> 33 | P14: =IF(N(J14)<=0,"",REPT("|",MIN(N(J14),25))) -> ||||||||||
B15: =IFERROR(INDEX(Tracker!$A$3:$A$100, MATCH(_xlfn.SINGLE(_xlfn.AGGREGATE(15, 6, Tracker!$CG$3:$CG$100, 6)), Tracker!$CG$3:$CG$100, 0)), "") -> EPM_DIM_NOD | C15: =IF(B15 = "", "", IFERROR(INDEX(Tracker!$C$3:$C$100, MATCH(_xlfn.SINGLE(_xlfn.AGGREGATE(15, 6, Tracker!$CG$3:$CG$100, 6)), Tracker!$CG$3:$CG$100, 0)), "")) -> Sprint 17 | D15: =IF(B15 = "", "", IFERROR(INDEX(Tracker!$D$3:$D$100, MATCH(_xlfn.SINGLE(_xlfn.AGGREGATE(15, 6, Tracker!$CG$3:$CG$100, 6)), Tracker!$CG$3:$CG$100, 0)), "")) -> In Progress | E15: =IF(B15 = "", "", IFERROR(INDEX(Tracker!$E$3:$E$100, MATCH(_xlfn.SINGLE(_xlfn.AGGREGATE(15, 6, Tracker!$CG$3:$CG$100, 6)), Tracker!$CG$3:$CG$100, 0)), "")) -> Prod OUR | F15: =IF(B15 = "", "", IFERROR(INDEX(Tracker!$F$3:$F$100, MATCH(_xlfn.SINGLE(_xlfn.AGGREGATE(15, 6, Tracker!$CG$3:$CG$100, 6)), Tracker!$CG$3:$CG$100, 0)), "")) -> 46224 | G15: =IF(B15 = "", "", IFERROR(INDEX(Tracker!$G$3:$G$100, MATCH(_xlfn.SINGLE(_xlfn.AGGREGATE(15, 6, Tracker!$CG$3:$CG$100, 6)), Tracker!$CG$3:$CG$100, 0)), "")) -> 31 | I15: QA OUR | J15: =SUMPRODUCT((Tracker!$A$3:$A$100<>"")*(Tracker!$AL$3:$AL$100<>"Completed")*(Tracker!$AL$3:$AL$100<>"N/A")*(ISNUMBER(Tracker!$AJ$3:$AJ$100))*(N(Tracker!$AJ$3:$AJ$100)<TODAY())) -> 10 | K15: =SUMPRODUCT((Tracker!$A$3:$A$100<>"")*(Tracker!$AL$3:$AL$100<>"Completed")*(Tracker!$AL$3:$AL$100<>"N/A")*(ISNUMBER(Tracker!$AJ$3:$AJ$100))*(N(Tracker!$AJ$3:$AJ$100)>=TODAY())*(N(Tracker!$AJ$3:$AJ$100)<=TODAY()+7)) -> 0 | L15: =SUMPRODUCT((Tracker!$A$3:$A$100<>"")*(ISNUMBER(Tracker!$AJ$3:$AJ$100))*(Tracker!$AL$3:$AL$100="Blocked")) -> 0 | M15: =SUMPRODUCT((Tracker!$A$3:$A$100<>"")*(ISNUMBER(Tracker!$AM$3:$AM$100))*(Tracker!$AO$3:$AO$100="In Progress")) -> 0 | N15: =SUMPRODUCT((Tracker!$A$3:$A$100<>"")*(ISNUMBER(Tracker!$W$3:$W$100))*(Tracker!$X$3:$X$100<>"Completed")*(Tracker!$X$3:$X$100<>"Blocked")*(Tracker!$X$3:$X$100<>"In Progress")) -> 43 | O15: =SUMPRODUCT((Tracker!$A$3:$A$100<>"")*(ISNUMBER(Tracker!$W$3:$W$100))*(Tracker!$X$3:$X$100="Completed")) -> 0 | P15: =IF(N(J15)<=0,"",REPT("|",MIN(N(J15),25))) -> ||||||||||
B16: =IFERROR(INDEX(Tracker!$A$3:$A$100, MATCH(_xlfn.SINGLE(_xlfn.AGGREGATE(15, 6, Tracker!$CG$3:$CG$100, 7)), Tracker!$CG$3:$CG$100, 0)), "") -> EPM_UI PUSH | C16: =IF(B16 = "", "", IFERROR(INDEX(Tracker!$C$3:$C$100, MATCH(_xlfn.SINGLE(_xlfn.AGGREGATE(15, 6, Tracker!$CG$3:$CG$100, 7)), Tracker!$CG$3:$CG$100, 0)), "")) -> Sprint 17 | D16: =IF(B16 = "", "", IFERROR(INDEX(Tracker!$D$3:$D$100, MATCH(_xlfn.SINGLE(_xlfn.AGGREGATE(15, 6, Tracker!$CG$3:$CG$100, 7)), Tracker!$CG$3:$CG$100, 0)), "")) -> Yet to start | E16: =IF(B16 = "", "", IFERROR(INDEX(Tracker!$E$3:$E$100, MATCH(_xlfn.SINGLE(_xlfn.AGGREGATE(15, 6, Tracker!$CG$3:$CG$100, 7)), Tracker!$CG$3:$CG$100, 0)), "")) -> Prod OUR | F16: =IF(B16 = "", "", IFERROR(INDEX(Tracker!$F$3:$F$100, MATCH(_xlfn.SINGLE(_xlfn.AGGREGATE(15, 6, Tracker!$CG$3:$CG$100, 7)), Tracker!$CG$3:$CG$100, 0)), "")) -> 46224 | G16: =IF(B16 = "", "", IFERROR(INDEX(Tracker!$G$3:$G$100, MATCH(_xlfn.SINGLE(_xlfn.AGGREGATE(15, 6, Tracker!$CG$3:$CG$100, 7)), Tracker!$CG$3:$CG$100, 0)), "")) -> 31 | I16: QA Service Request | J16: =SUMPRODUCT((Tracker!$A$3:$A$100<>"")*(Tracker!$AO$3:$AO$100<>"Completed")*(Tracker!$AO$3:$AO$100<>"N/A")*(ISNUMBER(Tracker!$AM$3:$AM$100))*(N(Tracker!$AM$3:$AM$100)<TODAY())) -> 10 | K16: =SUMPRODUCT((Tracker!$A$3:$A$100<>"")*(Tracker!$AO$3:$AO$100<>"Completed")*(Tracker!$AO$3:$AO$100<>"N/A")*(ISNUMBER(Tracker!$AM$3:$AM$100))*(N(Tracker!$AM$3:$AM$100)>=TODAY())*(N(Tracker!$AM$3:$AM$100)<=TODAY()+7)) -> 0 | L16: =SUMPRODUCT((Tracker!$A$3:$A$100<>"")*(ISNUMBER(Tracker!$AM$3:$AM$100))*(Tracker!$AO$3:$AO$100="Blocked")) -> 0 | M16: =SUMPRODUCT((Tracker!$A$3:$A$100<>"")*(ISNUMBER(Tracker!$AW$3:$AW$100))*(Tracker!$AY$3:$AY$100="In Progress")) -> 0 | N16: =SUMPRODUCT((Tracker!$A$3:$A$100<>"")*(ISNUMBER(Tracker!$Y$3:$Y$100))*(Tracker!$Z$3:$Z$100<>"Completed")*(Tracker!$Z$3:$Z$100<>"Blocked")*(Tracker!$Z$3:$Z$100<>"In Progress")) -> 0 | O16: =SUMPRODUCT((Tracker!$A$3:$A$100<>"")*(ISNUMBER(Tracker!$Y$3:$Y$100))*(Tracker!$Z$3:$Z$100="Completed")) -> 0 | P16: =IF(N(J16)<=0,"",REPT("|",MIN(N(J16),25))) -> ||||||||||
B17: =IFERROR(INDEX(Tracker!$A$3:$A$100, MATCH(_xlfn.SINGLE(_xlfn.AGGREGATE(15, 6, Tracker!$CG$3:$CG$100, 8)), Tracker!$CG$3:$CG$100, 0)), "") -> AR80 | C17: =IF(B17 = "", "", IFERROR(INDEX(Tracker!$C$3:$C$100, MATCH(_xlfn.SINGLE(_xlfn.AGGREGATE(15, 6, Tracker!$CG$3:$CG$100, 8)), Tracker!$CG$3:$CG$100, 0)), "")) -> Sprint 17 | D17: =IF(B17 = "", "", IFERROR(INDEX(Tracker!$D$3:$D$100, MATCH(_xlfn.SINGLE(_xlfn.AGGREGATE(15, 6, Tracker!$CG$3:$CG$100, 8)), Tracker!$CG$3:$CG$100, 0)), "")) -> Yet to start | E17: =IF(B17 = "", "", IFERROR(INDEX(Tracker!$E$3:$E$100, MATCH(_xlfn.SINGLE(_xlfn.AGGREGATE(15, 6, Tracker!$CG$3:$CG$100, 8)), Tracker!$CG$3:$CG$100, 0)), "")) -> Prod OUR | F17: =IF(B17 = "", "", IFERROR(INDEX(Tracker!$F$3:$F$100, MATCH(_xlfn.SINGLE(_xlfn.AGGREGATE(15, 6, Tracker!$CG$3:$CG$100, 8)), Tracker!$CG$3:$CG$100, 0)), "")) -> 46224 | G17: =IF(B17 = "", "", IFERROR(INDEX(Tracker!$G$3:$G$100, MATCH(_xlfn.SINGLE(_xlfn.AGGREGATE(15, 6, Tracker!$CG$3:$CG$100, 8)), Tracker!$CG$3:$CG$100, 0)), "")) -> 31 | I17: QA File R-Task | J17: =SUMPRODUCT((Tracker!$A$3:$A$100<>"")*(Tracker!$AR$3:$AR$100<>"Completed")*(Tracker!$AR$3:$AR$100<>"N/A")*(ISNUMBER(Tracker!$AP$3:$AP$100))*(N(Tracker!$AP$3:$AP$100)<TODAY())) -> 4 | K17: =SUMPRODUCT((Tracker!$A$3:$A$100<>"")*(Tracker!$AR$3:$AR$100<>"Completed")*(Tracker!$AR$3:$AR$100<>"N/A")*(ISNUMBER(Tracker!$AP$3:$AP$100))*(N(Tracker!$AP$3:$AP$100)>=TODAY())*(N(Tracker!$AP$3:$AP$100)<=TODAY()+7)) -> 0 | L17: =SUMPRODUCT((Tracker!$A$3:$A$100<>"")*(ISNUMBER(Tracker!$AP$3:$AP$100))*(Tracker!$AR$3:$AR$100="Blocked")) -> 0 | M17: =SUMPRODUCT((Tracker!$A$3:$A$100<>"")*(ISNUMBER(Tracker!$AZ$3:$AZ$100))*(Tracker!$BB$3:$BB$100="In Progress")) -> 0 | N17: =SUMPRODUCT((Tracker!$A$3:$A$100<>"")*(ISNUMBER(Tracker!$AA$3:$AA$100))*(Tracker!$AB$3:$AB$100<>"Completed")*(Tracker!$AB$3:$AB$100<>"Blocked")*(Tracker!$AB$3:$AB$100<>"In Progress")) -> 4 | O17: =SUMPRODUCT((Tracker!$A$3:$A$100<>"")*(ISNUMBER(Tracker!$AA$3:$AA$100))*(Tracker!$AB$3:$AB$100="Completed")) -> 0 | P17: =IF(N(J17)<=0,"",REPT("|",MIN(N(J17),25))) -> ||||
B18: =IFERROR(INDEX(Tracker!$A$3:$A$100, MATCH(_xlfn.SINGLE(_xlfn.AGGREGATE(15, 6, Tracker!$CG$3:$CG$100, 9)), Tracker!$CG$3:$CG$100, 0)), "") -> BI80 | C18: =IF(B18 = "", "", IFERROR(INDEX(Tracker!$C$3:$C$100, MATCH(_xlfn.SINGLE(_xlfn.AGGREGATE(15, 6, Tracker!$CG$3:$CG$100, 9)), Tracker!$CG$3:$CG$100, 0)), "")) -> Sprint 17 | D18: =IF(B18 = "", "", IFERROR(INDEX(Tracker!$D$3:$D$100, MATCH(_xlfn.SINGLE(_xlfn.AGGREGATE(15, 6, Tracker!$CG$3:$CG$100, 9)), Tracker!$CG$3:$CG$100, 0)), "")) -> Yet to start | E18: =IF(B18 = "", "", IFERROR(INDEX(Tracker!$E$3:$E$100, MATCH(_xlfn.SINGLE(_xlfn.AGGREGATE(15, 6, Tracker!$CG$3:$CG$100, 9)), Tracker!$CG$3:$CG$100, 0)), "")) -> Prod OUR | F18: =IF(B18 = "", "", IFERROR(INDEX(Tracker!$F$3:$F$100, MATCH(_xlfn.SINGLE(_xlfn.AGGREGATE(15, 6, Tracker!$CG$3:$CG$100, 9)), Tracker!$CG$3:$CG$100, 0)), "")) -> 46224 | G18: =IF(B18 = "", "", IFERROR(INDEX(Tracker!$G$3:$G$100, MATCH(_xlfn.SINGLE(_xlfn.AGGREGATE(15, 6, Tracker!$CG$3:$CG$100, 9)), Tracker!$CG$3:$CG$100, 0)), "")) -> 31 | I18: Prod R-Task | J18: =SUMPRODUCT((Tracker!$A$3:$A$100<>"")*(Tracker!$AW$3:$AW$100<>"Completed")*(Tracker!$AW$3:$AW$100<>"N/A")*(ISNUMBER(Tracker!$AU$3:$AU$100))*(N(Tracker!$AU$3:$AU$100)<TODAY())) -> 10 | K18: =SUMPRODUCT((Tracker!$A$3:$A$100<>"")*(Tracker!$AW$3:$AW$100<>"Completed")*(Tracker!$AW$3:$AW$100<>"N/A")*(ISNUMBER(Tracker!$AU$3:$AU$100))*(N(Tracker!$AU$3:$AU$100)>=TODAY())*(N(Tracker!$AU$3:$AU$100)<=TODAY()+7)) -> 0 | L18: =SUMPRODUCT((Tracker!$A$3:$A$100<>"")*(ISNUMBER(Tracker!$AU$3:$AU$100))*(Tracker!$AW$3:$AW$100="Blocked")) -> 0 | M18: =SUMPRODUCT((Tracker!$A$3:$A$100<>"")*(ISNUMBER(Tracker!$BC$3:$BC$100))*(Tracker!$BE$3:$BE$100="In Progress")) -> 0 | N18: =SUMPRODUCT((Tracker!$A$3:$A$100<>"")*(ISNUMBER(Tracker!$AC$3:$AC$100))*(Tracker!$AD$3:$AD$100<>"Completed")*(Tracker!$AD$3:$AD$100<>"Blocked")*(Tracker!$AD$3:$AD$100<>"In Progress")) -> 0 | O18: =SUMPRODUCT((Tracker!$A$3:$A$100<>"")*(ISNUMBER(Tracker!$AC$3:$AC$100))*(Tracker!$AD$3:$AD$100="Completed")) -> 0 | P18: =IF(N(J18)<=0,"",REPT("|",MIN(N(J18),25))) -> ||||||||||
B19: =IFERROR(INDEX(Tracker!$A$3:$A$100, MATCH(_xlfn.SINGLE(_xlfn.AGGREGATE(15, 6, Tracker!$CG$3:$CG$100, 10)), Tracker!$CG$3:$CG$100, 0)), "") -> CBP | C19: =IF(B19 = "", "", IFERROR(INDEX(Tracker!$C$3:$C$100, MATCH(_xlfn.SINGLE(_xlfn.AGGREGATE(15, 6, Tracker!$CG$3:$CG$100, 10)), Tracker!$CG$3:$CG$100, 0)), "")) -> Sprint 17 | D19: =IF(B19 = "", "", IFERROR(INDEX(Tracker!$D$3:$D$100, MATCH(_xlfn.SINGLE(_xlfn.AGGREGATE(15, 6, Tracker!$CG$3:$CG$100, 10)), Tracker!$CG$3:$CG$100, 0)), "")) -> Yet to start | E19: =IF(B19 = "", "", IFERROR(INDEX(Tracker!$E$3:$E$100, MATCH(_xlfn.SINGLE(_xlfn.AGGREGATE(15, 6, Tracker!$CG$3:$CG$100, 10)), Tracker!$CG$3:$CG$100, 0)), "")) -> Prod OUR | F19: =IF(B19 = "", "", IFERROR(INDEX(Tracker!$F$3:$F$100, MATCH(_xlfn.SINGLE(_xlfn.AGGREGATE(15, 6, Tracker!$CG$3:$CG$100, 10)), Tracker!$CG$3:$CG$100, 0)), "")) -> 46224 | G19: =IF(B19 = "", "", IFERROR(INDEX(Tracker!$G$3:$G$100, MATCH(_xlfn.SINGLE(_xlfn.AGGREGATE(15, 6, Tracker!$CG$3:$CG$100, 10)), Tracker!$CG$3:$CG$100, 0)), "")) -> 31 | I19: Prod OUR | J19: =SUMPRODUCT((Tracker!$A$3:$A$100<>"")*(Tracker!$AZ$3:$AZ$100<>"Completed")*(Tracker!$AZ$3:$AZ$100<>"N/A")*(ISNUMBER(Tracker!$AX$3:$AX$100))*(N(Tracker!$AX$3:$AX$100)<TODAY())) -> 43 | K19: =SUMPRODUCT((Tracker!$A$3:$A$100<>"")*(Tracker!$AZ$3:$AZ$100<>"Completed")*(Tracker!$AZ$3:$AZ$100<>"N/A")*(ISNUMBER(Tracker!$AX$3:$AX$100))*(N(Tracker!$AX$3:$AX$100)>=TODAY())*(N(Tracker!$AX$3:$AX$100)<=TODAY()+7)) -> 0 | L19: =SUMPRODUCT((Tracker!$A$3:$A$100<>"")*(ISNUMBER(Tracker!$AX$3:$AX$100))*(Tracker!$AZ$3:$AZ$100="Blocked")) -> 0 | M19: =SUMPRODUCT((Tracker!$A$3:$A$100<>"")*(ISNUMBER(Tracker!$AA$3:$AA$100))*(Tracker!$AC$3:$AC$100="In Progress")) -> 0 | N19: =SUMPRODUCT((Tracker!$A$3:$A$100<>"")*(ISNUMBER(Tracker!$AG$3:$AG$100))*(Tracker!$AH$3:$AH$100<>"Completed")*(Tracker!$AH$3:$AH$100<>"Blocked")*(Tracker!$AH$3:$AH$100<>"In Progress")) -> 43 | O19: =SUMPRODUCT((Tracker!$A$3:$A$100<>"")*(ISNUMBER(Tracker!$AG$3:$AG$100))*(Tracker!$AH$3:$AH$100="Completed")) -> 0 | P19: =IF(N(J19)<=0,"",REPT("|",MIN(N(J19),25))) -> |||||||||||||||||||||||||
B20: =IFERROR(INDEX(Tracker!$A$3:$A$100, MATCH(_xlfn.SINGLE(_xlfn.AGGREGATE(15, 6, Tracker!$CG$3:$CG$100, 11)), Tracker!$CG$3:$CG$100, 0)), "") -> CI | C20: =IF(B20 = "", "", IFERROR(INDEX(Tracker!$C$3:$C$100, MATCH(_xlfn.SINGLE(_xlfn.AGGREGATE(15, 6, Tracker!$CG$3:$CG$100, 11)), Tracker!$CG$3:$CG$100, 0)), "")) -> Sprint 17 | D20: =IF(B20 = "", "", IFERROR(INDEX(Tracker!$D$3:$D$100, MATCH(_xlfn.SINGLE(_xlfn.AGGREGATE(15, 6, Tracker!$CG$3:$CG$100, 11)), Tracker!$CG$3:$CG$100, 0)), "")) -> Yet to start | E20: =IF(B20 = "", "", IFERROR(INDEX(Tracker!$E$3:$E$100, MATCH(_xlfn.SINGLE(_xlfn.AGGREGATE(15, 6, Tracker!$CG$3:$CG$100, 11)), Tracker!$CG$3:$CG$100, 0)), "")) -> Prod OUR | F20: =IF(B20 = "", "", IFERROR(INDEX(Tracker!$F$3:$F$100, MATCH(_xlfn.SINGLE(_xlfn.AGGREGATE(15, 6, Tracker!$CG$3:$CG$100, 11)), Tracker!$CG$3:$CG$100, 0)), "")) -> 46224 | G20: =IF(B20 = "", "", IFERROR(INDEX(Tracker!$G$3:$G$100, MATCH(_xlfn.SINGLE(_xlfn.AGGREGATE(15, 6, Tracker!$CG$3:$CG$100, 11)), Tracker!$CG$3:$CG$100, 0)), "")) -> 31 | I20: Prod Service Request | J20: =SUMPRODUCT((Tracker!$A$3:$A$100<>"")*(Tracker!$BC$3:$BC$100<>"Completed")*(Tracker!$BC$3:$BC$100<>"N/A")*(ISNUMBER(Tracker!$BA$3:$BA$100))*(N(Tracker!$BA$3:$BA$100)<TODAY())) -> 43 | K20: =SUMPRODUCT((Tracker!$A$3:$A$100<>"")*(Tracker!$BC$3:$BC$100<>"Completed")*(Tracker!$BC$3:$BC$100<>"N/A")*(ISNUMBER(Tracker!$BA$3:$BA$100))*(N(Tracker!$BA$3:$BA$100)>=TODAY())*(N(Tracker!$BA$3:$BA$100)<=TODAY()+7)) -> 0 | L20: =SUMPRODUCT((Tracker!$A$3:$A$100<>"")*(ISNUMBER(Tracker!$BA$3:$BA$100))*(Tracker!$BC$3:$BC$100="Blocked")) -> 0 | M20: =SUMPRODUCT((Tracker!$A$3:$A$100<>"")*(ISNUMBER(Tracker!$BM$3:$BM$100))*(Tracker!$BN$3:$BN$100="In Progress")) -> 0 | N20: =SUMPRODUCT((Tracker!$A$3:$A$100<>"")*(ISNUMBER(Tracker!$AE$3:$AE$100))*(Tracker!$AF$3:$AF$100<>"Completed")*(Tracker!$AF$3:$AF$100<>"Blocked")*(Tracker!$AF$3:$AF$100<>"In Progress")) -> 0 | O20: =SUMPRODUCT((Tracker!$A$3:$A$100<>"")*(ISNUMBER(Tracker!$AE$3:$AE$100))*(Tracker!$AF$3:$AF$100="Completed")) -> 0 | P20: =IF(N(J20)<=0,"",REPT("|",MIN(N(J20),25))) -> |||||||||||||||||||||||||
B21: =IFERROR(INDEX(Tracker!$A$3:$A$100, MATCH(_xlfn.SINGLE(_xlfn.AGGREGATE(15, 6, Tracker!$CG$3:$CG$100, 12)), Tracker!$CG$3:$CG$100, 0)), "") -> CI_MART | C21: =IF(B21 = "", "", IFERROR(INDEX(Tracker!$C$3:$C$100, MATCH(_xlfn.SINGLE(_xlfn.AGGREGATE(15, 6, Tracker!$CG$3:$CG$100, 12)), Tracker!$CG$3:$CG$100, 0)), "")) -> Sprint 17 | D21: =IF(B21 = "", "", IFERROR(INDEX(Tracker!$D$3:$D$100, MATCH(_xlfn.SINGLE(_xlfn.AGGREGATE(15, 6, Tracker!$CG$3:$CG$100, 12)), Tracker!$CG$3:$CG$100, 0)), "")) -> Yet to start | E21: =IF(B21 = "", "", IFERROR(INDEX(Tracker!$E$3:$E$100, MATCH(_xlfn.SINGLE(_xlfn.AGGREGATE(15, 6, Tracker!$CG$3:$CG$100, 12)), Tracker!$CG$3:$CG$100, 0)), "")) -> Prod OUR | F21: =IF(B21 = "", "", IFERROR(INDEX(Tracker!$F$3:$F$100, MATCH(_xlfn.SINGLE(_xlfn.AGGREGATE(15, 6, Tracker!$CG$3:$CG$100, 12)), Tracker!$CG$3:$CG$100, 0)), "")) -> 46224 | G21: =IF(B21 = "", "", IFERROR(INDEX(Tracker!$G$3:$G$100, MATCH(_xlfn.SINGLE(_xlfn.AGGREGATE(15, 6, Tracker!$CG$3:$CG$100, 12)), Tracker!$CG$3:$CG$100, 0)), "")) -> 31 | I21: Prod File R-Task | J21: =SUMPRODUCT((Tracker!$A$3:$A$100<>"")*(Tracker!$BF$3:$BF$100<>"Completed")*(Tracker!$BF$3:$BF$100<>"N/A")*(ISNUMBER(Tracker!$BD$3:$BD$100))*(N(Tracker!$BD$3:$BD$100)<TODAY())) -> 4 | K21: =SUMPRODUCT((Tracker!$A$3:$A$100<>"")*(Tracker!$BF$3:$BF$100<>"Completed")*(Tracker!$BF$3:$BF$100<>"N/A")*(ISNUMBER(Tracker!$BD$3:$BD$100))*(N(Tracker!$BD$3:$BD$100)>=TODAY())*(N(Tracker!$BD$3:$BD$100)<=TODAY()+7)) -> 0 | L21: =SUMPRODUCT((Tracker!$A$3:$A$100<>"")*(ISNUMBER(Tracker!$BD$3:$BD$100))*(Tracker!$BF$3:$BF$100="Blocked")) -> 0 | M21: =SUMPRODUCT((Tracker!$A$3:$A$100<>"")*(ISNUMBER(Tracker!$BO$3:$BO$100))*(Tracker!$BP$3:$BP$100="In Progress")) -> 0 | N21: =SUM(N10:N20) -> 190 | O21: =SUM(O10:O20) -> 40
I22: Sprint Readiness | J22: =SUMPRODUCT((Tracker!$A$3:$A$100<>"")*(Tracker!$P$3:$P$100<>"Completed")*(Tracker!$P$3:$P$100<>"N/A")*(ISNUMBER(Tracker!$O$3:$O$100))*(N(Tracker!$O$3:$O$100)<TODAY())) -> 36 | K22: =SUMPRODUCT((Tracker!$A$3:$A$100<>"")*(Tracker!$P$3:$P$100<>"Completed")*(Tracker!$P$3:$P$100<>"N/A")*(ISNUMBER(Tracker!$O$3:$O$100))*(N(Tracker!$O$3:$O$100)>=TODAY())*(N(Tracker!$O$3:$O$100)<=TODAY()+7)) -> 0 | L22: =SUMPRODUCT((Tracker!$A$3:$A$100<>"")*(ISNUMBER(Tracker!$O$3:$O$100))*(Tracker!$P$3:$P$100="Blocked")) -> 0
I23: CAB | J23: =SUMPRODUCT((Tracker!$A$3:$A$100<>"")*(Tracker!$BJ$3:$BJ$100<>"Completed")*(Tracker!$BJ$3:$BJ$100<>"N/A")*(ISNUMBER(Tracker!$BI$3:$BI$100))*(N(Tracker!$BI$3:$BI$100)<TODAY())) -> 0 | K23: =SUMPRODUCT((Tracker!$A$3:$A$100<>"")*(Tracker!$BJ$3:$BJ$100<>"Completed")*(Tracker!$BJ$3:$BJ$100<>"N/A")*(ISNUMBER(Tracker!$BI$3:$BI$100))*(N(Tracker!$BI$3:$BI$100)>=TODAY())*(N(Tracker!$BI$3:$BI$100)<=TODAY()+7)) -> 0 | L23: =SUMPRODUCT((Tracker!$A$3:$A$100<>"")*(ISNUMBER(Tracker!$BI$3:$BI$100))*(Tracker!$BJ$3:$BJ$100="Blocked")) -> 0
I24: Code Review | J24: =SUMPRODUCT((Tracker!$A$3:$A$100<>"")*(Tracker!$BL$3:$BL$100<>"Completed")*(Tracker!$BL$3:$BL$100<>"N/A")*(ISNUMBER(Tracker!$BK$3:$BK$100))*(N(Tracker!$BK$3:$BK$100)<TODAY())) -> 0 | K24: =SUMPRODUCT((Tracker!$A$3:$A$100<>"")*(Tracker!$BL$3:$BL$100<>"Completed")*(Tracker!$BL$3:$BL$100<>"N/A")*(ISNUMBER(Tracker!$BK$3:$BK$100))*(N(Tracker!$BK$3:$BK$100)>=TODAY())*(N(Tracker!$BK$3:$BK$100)<=TODAY()+7)) -> 0 | L24: =SUMPRODUCT((Tracker!$A$3:$A$100<>"")*(ISNUMBER(Tracker!$BK$3:$BK$100))*(Tracker!$BL$3:$BL$100="Blocked")) -> 0
I25: Code Review Invite | J25: =SUMPRODUCT((Tracker!$A$3:$A$100<>"")*(Tracker!$BN$3:$BN$100<>"Completed")*(Tracker!$BN$3:$BN$100<>"N/A")*(ISNUMBER(Tracker!$BM$3:$BM$100))*(N(Tracker!$BM$3:$BM$100)<TODAY())) -> 0 | K25: =SUMPRODUCT((Tracker!$A$3:$A$100<>"")*(Tracker!$BN$3:$BN$100<>"Completed")*(Tracker!$BN$3:$BN$100<>"N/A")*(ISNUMBER(Tracker!$BM$3:$BM$100))*(N(Tracker!$BM$3:$BM$100)>=TODAY())*(N(Tracker!$BM$3:$BM$100)<=TODAY()+7)) -> 0 | L25: =SUMPRODUCT((Tracker!$A$3:$A$100<>"")*(ISNUMBER(Tracker!$BM$3:$BM$100))*(Tracker!$BN$3:$BN$100="Blocked")) -> 0

Sheet Tracker
A1: CONTROL STRIP - always visible | H1: INPUTS - type dates | K1: AUDIT - Excel fills | N1: READY / READINESS | Q1: DEV DB REQUESTS | Z1: DEV FILE REQUESTS | AG1: QA DB REQUESTS | AP1: QA FILE REQUESTS | AU1: PROD DB REQUESTS | BD1: PROD FILE REQUESTS | BI1: RELEASE GOVERNANCE | BP1: VALIDATION
A2: Application | B2: Responsible PM | C2: Sprint | D2: Overall Status | E2: Next Action | F2: Next Action Date | G2: Days Overdue | H2: Sprint Start | I2: Sprint End | J2: Release Date | K2: Effective Sprint Start | L2: Effective Sprint End | M2: Effective Release Date | N2: App Ready By | O2: Sprint Readiness Date | P2: Sprint Readiness Status | Q2: Dev R-Task | R2: Raised On | S2: Dev R-Task Status | T2: Dev OUR | U2: Raised On | V2: Dev OUR Status | W2: Dev Service Request | X2: Raised On | Y2: Dev SR Status | Z2: File Type (all envs) | AA2: Dev File R-Task | AB2: Raised On | AC2: Dev File R-Task Status | AD2: IAM | AE2: Ownership Identified | AF2: Frequency (all envs) | AG2: QA R-Task | AH2: Raised On | AI2: QA R-Task Status | AJ2: QA OUR | AK2: Raised On | AL2: QA OUR Status | AM2: QA Service Request | AN2: Raised On | AO2: QA SR Status | AP2: QA File R-Task | AQ2: Raised On | AR2: QA File R-Task Status | AS2: IAM | AT2: Ownership Identified | AU2: Prod R-Task | AV2: Raised On | AW2: Prod R-Task Status | AX2: Prod OUR | AY2: Raised On | AZ2: Prod OUR Status | BA2: Prod Service Request | BB2: Raised On | BC2: Prod SR Status | BD2: Prod File R-Task | BE2: Raised On | BF2: Prod File R-Task Status | BG2: IAM | BH2: Ownership Identified | BI2: CAB Date | BJ2: CAB Status | BK2: Code Review Date | BL2: Code Review Status | BM2: Code Review Invite | BN2: CR Invite Status | BO2: Release Status | BP2: Validation / Notes
A3: CI_MART | B3: Sharath Kotha | C3: Sprint 17 | D3: =IF(A3="","",IF(((S3="Blocked")+(V3="Blocked")+(Y3="Blocked")+(AC3="Blocked")+(AI3="Blocked")+(AL3="Blocked")+(AO3="Blocked")+(AR3="Blocked")+(AW3="Blocked")+(AZ3="Blocked")+(BC3="Blocked")+(BF3="Blocked")+(P3="Blocked")+(BJ3="Blocked")+(BL3="Blocked")+(BN3="Blocked")+(BO3="Blocked"))>0,"Blocked",IF((ISNUMBER(Q3)+ISNUMBER(T3)+ISNUMBER(W3)+ISNUMBER(AA3)+ISNUMBER(AG3)+ISNUMBER(AJ3)+ISNUMBER(AM3)+ISNUMBER(AP3)+ISNUMBER(AU3)+ISNUMBER(AX3)+ISNUMBER(BA3)+ISNUMBER(BD3)+ISNUMBER(O3)+ISNUMBER(BI3)+ISNUMBER(BK3)+ISNUMBER(BM3))=0,"Yet to start",IF(AND(OR(NOT(ISNUMBER(Q3)),S3="Completed",S3="N/A"),OR(NOT(ISNUMBER(T3)),V3="Completed",V3="N/A"),OR(NOT(ISNUMBER(W3)),Y3="Completed",Y3="N/A"),OR(NOT(ISNUMBER(AA3)),AC3="Completed",AC3="N/A"),OR(NOT(ISNUMBER(AG3)),AI3="Completed",AI3="N/A"),OR(NOT(ISNUMBER(AJ3)),AL3="Completed",AL3="N/A"),OR(NOT(ISNUMBER(AM3)),AO3="Completed",AO3="N/A"),OR(NOT(ISNUMBER(AP3)),AR3="Completed",AR3="N/A"),OR(NOT(ISNUMBER(AU3)),AW3="Completed",AW3="N/A"),OR(NOT(ISNUMBER(AX3)),AZ3="Completed",AZ3="N/A"),OR(NOT(ISNUMBER(BA3)),BC3="Completed",BC3="N/A"),OR(NOT(ISNUMBER(BD3)),BF3="Completed",BF3="N/A"),OR(NOT(ISNUMBER(O3)),P3="Completed",P3="N/A"),OR(NOT(ISNUMBER(BI3)),BJ3="Completed",BJ3="N/A"),OR(NOT(ISNUMBER(BK3)),BL3="Completed",BL3="N/A"),OR(NOT(ISNUMBER(BM3)),BN3="Completed",BN3="N/A"),OR(BO3="Completed",BO3="N/A")),"Completed",IF(((S3="In Progress")+(V3="In Progress")+(Y3="In Progress")+(AC3="In Progress")+(AI3="In Progress")+(AL3="In Progress")+(AO3="In Progress")+(AR3="In Progress")+(AW3="In Progress")+(AZ3="In Progress")+(BC3="In Progress")+(BF3="In Progress")+(P3="In Progress")+(BJ3="In Progress")+(BL3="In Progress")+(BN3="In Progress")+(BO3="In Progress"))>0,"In Progress","Yet to start"))))) -> Yet to start | E3: =IF(A3="","",IF(F3="","All complete",INDEX({"Dev R-Task","Dev OUR","Dev Service Request","Dev File R-Task","QA R-Task","QA OUR","QA Service Request","QA File R-Task","Prod R-Task","Prod OUR","Prod Service Request","Prod File R-Task","Sprint Readiness","Code Review Invite","Code Review","CAB"},MATCH(F3,BQ3:CF3,0)))) -> Prod OUR | F3: =IF(A3="","",IF(COUNT(BQ3:CF3)=0,"",MIN(BQ3:CF3))) -> 46224 | G3: =IF(A3="","",MAX(0,IF(AND(ISNUMBER(Q3),S3<>"Completed",S3<>"N/A",Q3<TODAY()),TODAY()-Q3,0),IF(AND(ISNUMBER(T3),V3<>"Completed",V3<>"N/A",T3<TODAY()),TODAY()-T3,0),IF(AND(ISNUMBER(W3),Y3<>"Completed",Y3<>"N/A",W3<TODAY()),TODAY()-W3,0),IF(AND(ISNUMBER(AA3),AC3<>"Completed",AC3<>"N/A",AA3<TODAY()),TODAY()-AA3,0),IF(AND(ISNUMBER(AG3),AI3<>"Completed",AI3<>"N/A",AG3<TODAY()),TODAY()-AG3,0),IF(AND(ISNUMBER(AJ3),AL3<>"Completed",AL3<>"N/A",AJ3<TODAY()),TODAY()-AJ3,0),IF(AND(ISNUMBER(AM3),AO3<>"Completed",AO3<>"N/A",AM3<TODAY()),TODAY()-AM3,0),IF(AND(ISNUMBER(AP3),AR3<>"Completed",AR3<>"N/A",AP3<TODAY()),TODAY()-AP3,0),IF(AND(ISNUMBER(AU3),AW3<>"Completed",AW3<>"N/A",AU3<TODAY()),TODAY()-AU3,0),IF(AND(ISNUMBER(AX3),AZ3<>"Completed",AZ3<>"N/A",AX3<TODAY()),TODAY()-AX3,0),IF(AND(ISNUMBER(BA3),BC3<>"Completed",BC3<>"N/A",BA3<TODAY()),TODAY()-BA3,0),IF(AND(ISNUMBER(BD3),BF3<>"Completed",BF3<>"N/A",BD3<TODAY()),TODAY()-BD3,0),IF(AND(ISNUMBER(O3),P3<>"Completed",P3<>"N/A",O3<TODAY()),TODAY()-O3,0),IF(AND(ISNUMBER(BM3),BN3<>"Completed",BN3<>"N/A",BM3<TODAY()),TODAY()-BM3,0),IF(AND(ISNUMBER(BK3),BL3<>"Completed",BL3<>"N/A",BK3<TODAY()),TODAY()-BK3,0),IF(AND(ISNUMBER(BI3),BJ3<>"Completed",BJ3<>"N/A",BI3<TODAY()),TODAY()-BI3,0))) -> 31 | H3: 46232 | I3: 46245 | J3: 46300 | K3: =IF(ISNUMBER(H3),H3,IF(ISNUMBER(M3),M3-WEEKDAY(M3,2)+1-7,"")) -> 46232 | L3: =IF(ISNUMBER(I3),I3,IF(ISNUMBER(H3),WORKDAY(H3,SprintWorkingDays-1),IF(ISNUMBER(K3),WORKDAY(K3,SprintWorkingDays-1),""))) -> 46245 | M3: =IF(ISNUMBER(J3),J3,IF(ISNUMBER(I3),I3-IF(OR(WEEKDAY(I3,2)=2,WEEKDAY(I3,2)=4),0,IF(WEEKDAY(I3,2)=3,1,IF(WEEKDAY(I3,2)=1,4,WEEKDAY(I3,2)-4))),IF(ISNUMBER(H3),WORKDAY(H3,SprintWorkingDays-1)-IF(OR(WEEKDAY(WORKDAY(H3,SprintWorkingDays-1),2)=2,WEEKDAY(WORKDAY(H3,SprintWorkingDays-1),2)=4),0,IF(WEEKDAY(WORKDAY(H3,SprintWorkingDays-1),2)=3,1,IF(WEEKDAY(WORKDAY(H3,SprintWorkingDays-1),2)=1,4,WEEKDAY(WORKDAY(H3,SprintWorkingDays-1),2)-4))),""))) -> 46300 | N3: =IF(NOT(ISNUMBER(K3)),"",WORKDAY(K3,ReadyOffsetWD)) -> 46231 | O3: =IF(NOT(ISNUMBER(K3)),"",WORKDAY(K3,SprintReadinessOffsetWD)) -> 46230 | P3: Completed | Q3: =IF(A3="","",IF(V3="N/A",IF(NOT(ISNUMBER(W3)),"",WORKDAY(W3,RTSKOffsetFromOUR_WD)),IF(NOT(ISNUMBER(T3)),"",WORKDAY(T3,RTSKOffsetFromOUR_WD)))) -> 46220 | R3: 46233 | S3: Completed | T3: =IF(OR(A3="",V3="N/A"),"",IF(NOT(ISNUMBER(W3)),"",WORKDAY(W3,OUROffsetFromSR_WD))) -> 46224 | U3: 46220 | V3: Completed | W3: =IF(OR(A3="",NOT(ISNUMBER(K3))),"",WORKDAY(K3,SROffsetFromStartWD)) -> 46225 | X3: 46220 | Y3: Completed | Z3: N/A | AA3: =IF(OR(Z3="",Z3="N/A"),"",IF(ISNUMBER(Q3),Q3,"")) | AF3: =IF(Z3="N/A","N/A","") -> N/A | AG3: =IF(NOT(ISNUMBER(Q3)),"",Q3) -> 46220 | AH3: 46225 | AI3: Completed | AJ3: =IF(OR(AL3="N/A",NOT(ISNUMBER(T3))),"",T3) -> 46224 | AK3: 46225 | AL3: Completed | AM3: =IF(NOT(ISNUMBER(W3)),"",W3) -> 46225 | AN3: 46225 | AO3: Completed | AP3: =IF(OR(Z3="",Z3="N/A"),"",IF(ISNUMBER(AG3),AG3,"")) | AU3: =IF(NOT(ISNUMBER(Q3)),"",Q3) -> 46220 | AW3: Completed | AX3: =IF(OR(AZ3="N/A",NOT(ISNUMBER(T3))),"",T3) -> 46224 | BA3: =IF(NOT(ISNUMBER(W3)),"",W3) -> 46225 | BD3: =IF(OR(Z3="",Z3="N/A"),"",IF(ISNUMBER(AU3),AU3,"")) | BI3: 46300 | BK3: =IF(NOT(ISNUMBER(BI3)),"",IF(WEEKDAY(BI3-CodeReviewCalendarDays,2)>5,BI3-CodeReviewCalendarDays-(WEEKDAY(BI3-CodeReviewCalendarDays,2)-5),BI3-CodeReviewCalendarDays)) -> 46297 | BM3: =IF(NOT(ISNUMBER(BK3)),"",IF(WEEKDAY(BK3-CodeReviewInviteCalendarDays,2)>5,BK3-CodeReviewInviteCalendarDays-(WEEKDAY(BK3-CodeReviewInviteCalendarDays,2)-5),BK3-CodeReviewInviteCalendarDays)) -> 46293 | BP3: =IF(A3="","",IF(IF(AND(ISNUMBER(J3),WEEKDAY(J3,2)<>2,WEEKDAY(J3,2)<>4)," | Release must be Tuesday or Thursday","")&IF(AND(ISNUMBER(H3),WEEKDAY(H3,2)<>1)," | Sprint Start is not a Monday - dates still calculated from the date entered","")&IF(AND(A3<>"",NOT(ISNUMBER(H3)),NOT(ISNUMBER(J3)))," | Enter Sprint Start or Release Date","")&IF(AND(ISNUMBER(F3),F3<TODAY(),D3<>"Completed")," | One or more raise-by dates are in the past and not completed","")&IF(AND(ISNUMBER(K3),K3-TODAY()<SprintWarningDays,K3>=TODAY(),OR(D3="Yet to start",D3="Blocked"))," | Sprint starts in under 10 days - raise access requests now","")&IF(AND(ISNUMBER(BM3),BN3<>"Completed",BN3<>"N/A",BM3-TODAY()<CodeReviewInviteCalendarDays)," | Code Review invite should be sent at least 4 days before Code Review","")="","",MID(IF(AND(ISNUMBER(J3),WEEKDAY(J3,2)<>2,WEEKDAY(J3,2)<>4)," | Release must be Tuesday or Thursday","")&IF(AND(ISNUMBER(H3),WEEKDAY(H3,2)<>1)," | Sprint Start is not a Monday - dates still calculated from the date entered","")&IF(AND(A3<>"",NOT(ISNUMBER(H3)),NOT(ISNUMBER(J3)))," | Enter Sprint Start or Release Date","")&IF(AND(ISNUMBER(F3),F3<TODAY(),D3<>"Completed")," | One or more raise-by dates are in the past and not completed","")&IF(AND(ISNUMBER(K3),K3-TODAY()<SprintWarningDays,K3>=TODAY(),OR(D3="Yet to start",D3="Blocked"))," | Sprint starts in under 10 days - raise access requests now","")&IF(AND(ISNUMBER(BM3),BN3<>"Completed",BN3<>"N/A",BM3-TODAY()<CodeReviewInviteCalendarDays)," | Code Review invite should be sent at least 4 days before Code Review",""),4,500))) -> Release must be Tuesday or Thursday | Sprint Start is not a Monday - dates still calculated from the date entered | One or more raise-by dates are in the past and not completed | BQ3: =IF(AND(ISNUMBER(Q3),S3<>"Completed",S3<>"N/A"),Q3,"") | BR3: =IF(AND(ISNUMBER(T3),V3<>"Completed",V3<>"N/A"),T3,"") | BS3: =IF(AND(ISNUMBER(W3),Y3<>"Completed",Y3<>"N/A"),W3,"") | BT3: =IF(AND(ISNUMBER(AA3),AC3<>"Completed",AC3<>"N/A"),AA3,"") | BU3: =IF(AND(ISNUMBER(AG3),AI3<>"Completed",AI3<>"N/A"),AG3,"") | BV3: =IF(AND(ISNUMBER(AJ3),AL3<>"Completed",AL3<>"N/A"),AJ3,"") | BW3: =IF(AND(ISNUMBER(AM3),AO3<>"Completed",AO3<>"N/A"),AM3,"") | BX3: =IF(AND(ISNUMBER(AP3),AR3<>"Completed",AR3<>"N/A"),AP3,"") | BY3: =IF(AND(ISNUMBER(AU3),AW3<>"Completed",AW3<>"N/A"),AU3,"") | BZ3: =IF(AND(ISNUMBER(AX3),AZ3<>"Completed",AZ3<>"N/A"),AX3,"") -> 46224 | CA3: =IF(AND(ISNUMBER(BA3),BC3<>"Completed",BC3<>"N/A"),BA3,"") -> 46225 | CB3: =IF(AND(ISNUMBER(BD3),BF3<>"Completed",BF3<>"N/A"),BD3,"") | CC3: =IF(AND(ISNUMBER(O3),P3<>"Completed",P3<>"N/A"),O3,"") | CD3: =IF(AND(ISNUMBER(BM3),BN3<>"Completed",BN3<>"N/A"),BM3,"") -> 46293 | CE3: =IF(AND(ISNUMBER(BK3),BL3<>"Completed",BL3<>"N/A"),BK3,"") -> 46297 | CF3: =IF(AND(ISNUMBER(BI3),BJ3<>"Completed",BJ3<>"N/A"),BI3,"") -> 46300 | CG3: =IF(OR(A3="",D3="Completed"),"",IF(N(G3)>0,1/(N(G3)+ROW()/100000),IF(ISNUMBER(F3),1000+F3+ROW()/100000,TODAY()+400+ROW()/100000))) -> 0.032258033
A4: CI | B4: Sharath Kotha | C4: Sprint 17 | D4: =IF(A4="","",IF(((S4="Blocked")+(V4="Blocked")+(Y4="Blocked")+(AC4="Blocked")+(AI4="Blocked")+(AL4="Blocked")+(AO4="Blocked")+(AR4="Blocked")+(AW4="Blocked")+(AZ4="Blocked")+(BC4="Blocked")+(BF4="Blocked")+(P4="Blocked")+(BJ4="Blocked")+(BL4="Blocked")+(BN4="Blocked")+(BO4="Blocked"))>0,"Blocked",IF((ISNUMBER(Q4)+ISNUMBER(T4)+ISNUMBER(W4)+ISNUMBER(AA4)+ISNUMBER(AG4)+ISNUMBER(AJ4)+ISNUMBER(AM4)+ISNUMBER(AP4)+ISNUMBER(AU4)+ISNUMBER(AX4)+ISNUMBER(BA4)+ISNUMBER(BD4)+ISNUMBER(O4)+ISNUMBER(BI4)+ISNUMBER(BK4)+ISNUMBER(BM4))=0,"Yet to start",IF(AND(OR(NOT(ISNUMBER(Q4)),S4="Completed",S4="N/A"),OR(NOT(ISNUMBER(T4)),V4="Completed",V4="N/A"),OR(NOT(ISNUMBER(W4)),Y4="Completed",Y4="N/A"),OR(NOT(ISNUMBER(AA4)),AC4="Completed",AC4="N/A"),OR(NOT(ISNUMBER(AG4)),AI4="Completed",AI4="N/A"),OR(NOT(ISNUMBER(AJ4)),AL4="Completed",AL4="N/A"),OR(NOT(ISNUMBER(AM4)),AO4="Completed",AO4="N/A"),OR(NOT(ISNUMBER(AP4)),AR4="Completed",AR4="N/A"),OR(NOT(ISNUMBER(AU4)),AW4="Completed",AW4="N/A"),OR(NOT(ISNUMBER(AX4)),AZ4="Completed",AZ4="N/A"),OR(NOT(ISNUMBER(BA4)),BC4="Completed",BC4="N/A"),OR(NOT(ISNUMBER(BD4)),BF4="Completed",BF4="N/A"),OR(NOT(ISNUMBER(O4)),P4="Completed",P4="N/A"),OR(NOT(ISNUMBER(BI4)),BJ4="Completed",BJ4="N/A"),OR(NOT(ISNUMBER(BK4)),BL4="Completed",BL4="N/A"),OR(NOT(ISNUMBER(BM4)),BN4="Completed",BN4="N/A"),OR(BO4="Completed",BO4="N/A")),"Completed",IF(((S4="In Progress")+(V4="In Progress")+(Y4="In Progress")+(AC4="In Progress")+(AI4="In Progress")+(AL4="In Progress")+(AO4="In Progress")+(AR4="In Progress")+(AW4="In Progress")+(AZ4="In Progress")+(BC4="In Progress")+(BF4="In Progress")+(P4="In Progress")+(BJ4="In Progress")+(BL4="In Progress")+(BN4="In Progress")+(BO4="In Progress"))>0,"In Progress","Yet to start"))))) -> Yet to start | E4: =IF(A4="","",IF(F4="","All complete",INDEX({"Dev R-Task","Dev OUR","Dev Service Request","Dev File R-Task","QA R-Task","QA OUR","QA Service Request","QA File R-Task","Prod R-Task","Prod OUR","Prod Service Request","Prod File R-Task","Sprint Readiness","Code Review Invite","Code Review","CAB"},MATCH(F4,BQ4:CF4,0)))) -> Prod OUR | F4: =IF(A4="","",IF(COUNT(BQ4:CF4)=0,"",MIN(BQ4:CF4))) -> 46224 | G4: =IF(A4="","",MAX(0,IF(AND(ISNUMBER(Q4),S4<>"Completed",S4<>"N/A",Q4<TODAY()),TODAY()-Q4,0),IF(AND(ISNUMBER(T4),V4<>"Completed",V4<>"N/A",T4<TODAY()),TODAY()-T4,0),IF(AND(ISNUMBER(W4),Y4<>"Completed",Y4<>"N/A",W4<TODAY()),TODAY()-W4,0),IF(AND(ISNUMBER(AA4),AC4<>"Completed",AC4<>"N/A",AA4<TODAY()),TODAY()-AA4,0),IF(AND(ISNUMBER(AG4),AI4<>"Completed",AI4<>"N/A",AG4<TODAY()),TODAY()-AG4,0),IF(AND(ISNUMBER(AJ4),AL4<>"Completed",AL4<>"N/A",AJ4<TODAY()),TODAY()-AJ4,0),IF(AND(ISNUMBER(AM4),AO4<>"Completed",AO4<>"N/A",AM4<TODAY()),TODAY()-AM4,0),IF(AND(ISNUMBER(AP4),AR4<>"Completed",AR4<>"N/A",AP4<TODAY()),TODAY()-AP4,0),IF(AND(ISNUMBER(AU4),AW4<>"Completed",AW4<>"N/A",AU4<TODAY()),TODAY()-AU4,0),IF(AND(ISNUMBER(AX4),AZ4<>"Completed",AZ4<>"N/A",AX4<TODAY()),TODAY()-AX4,0),IF(AND(ISNUMBER(BA4),BC4<>"Completed",BC4<>"N/A",BA4<TODAY()),TODAY()-BA4,0),IF(AND(ISNUMBER(BD4),BF4<>"Completed",BF4<>"N/A",BD4<TODAY()),TODAY()-BD4,0),IF(AND(ISNUMBER(O4),P4<>"Completed",P4<>"N/A",O4<TODAY()),TODAY()-O4,0),IF(AND(ISNUMBER(BM4),BN4<>"Completed",BN4<>"N/A",BM4<TODAY()),TODAY()-BM4,0),IF(AND(ISNUMBER(BK4),BL4<>"Completed",BL4<>"N/A",BK4<TODAY()),TODAY()-BK4,0),IF(AND(ISNUMBER(BI4),BJ4<>"Completed",BJ4<>"N/A",BI4<TODAY()),TODAY()-BI4,0))) -> 31 | H4: 46232 | I4: 46245 | J4: 46300 | K4: =IF(ISNUMBER(H4),H4,IF(ISNUMBER(M4),M4-WEEKDAY(M4,2)+1-7,"")) -> 46232 | L4: =IF(ISNUMBER(I4),I4,IF(ISNUMBER(H4),WORKDAY(H4,SprintWorkingDays-1),IF(ISNUMBER(K4),WORKDAY(K4,SprintWorkingDays-1),""))) -> 46245 | M4: =IF(ISNUMBER(J4),J4,IF(ISNUMBER(I4),I4-IF(OR(WEEKDAY(I4,2)=2,WEEKDAY(I4,2)=4),0,IF(WEEKDAY(I4,2)=3,1,IF(WEEKDAY(I4,2)=1,4,WEEKDAY(I4,2)-4))),IF(ISNUMBER(H4),WORKDAY(H4,SprintWorkingDays-1)-IF(OR(WEEKDAY(WORKDAY(H4,SprintWorkingDays-1),2)=2,WEEKDAY(WORKDAY(H4,SprintWorkingDays-1),2)=4),0,IF(WEEKDAY(WORKDAY(H4,SprintWorkingDays-1),2)=3,1,IF(WEEKDAY(WORKDAY(H4,SprintWorkingDays-1),2)=1,4,WEEKDAY(WORKDAY(H4,SprintWorkingDays-1),2)-4))),""))) -> 46300 | N4: =IF(NOT(ISNUMBER(K4)),"",WORKDAY(K4,ReadyOffsetWD)) -> 46231 | O4: =IF(NOT(ISNUMBER(K4)),"",WORKDAY(K4,SprintReadinessOffsetWD)) -> 46230 | P4: Completed | Q4: =IF(A4="","",IF(V4="N/A",IF(NOT(ISNUMBER(W4)),"",WORKDAY(W4,RTSKOffsetFromOUR_WD)),IF(NOT(ISNUMBER(T4)),"",WORKDAY(T4,RTSKOffsetFromOUR_WD)))) -> 46220 | R4: 46233 | S4: Completed | T4: =IF(OR(A4="",V4="N/A"),"",IF(NOT(ISNUMBER(W4)),"",WORKDAY(W4,OUROffsetFromSR_WD))) -> 46224 | U4: 46220 | V4: Completed | W4: =IF(OR(A4="",NOT(ISNUMBER(K4))),"",WORKDAY(K4,SROffsetFromStartWD)) -> 46225 | X4: 46220 | Y4: Completed | Z4: N/A | AA4: =IF(OR(Z4="",Z4="N/A"),"",IF(ISNUMBER(Q4),Q4,"")) | AF4: =IF(Z4="N/A","N/A","") -> N/A | AG4: =IF(NOT(ISNUMBER(Q4)),"",Q4) -> 46220 | AH4: 46225 | AI4: Completed | AJ4: =IF(OR(AL4="N/A",NOT(ISNUMBER(T4))),"",T4) -> 46224 | AK4: 46225 | AL4: Completed | AM4: =IF(NOT(ISNUMBER(W4)),"",W4) -> 46225 | AN4: 46225 | AO4: Completed | AP4: =IF(OR(Z4="",Z4="N/A"),"",IF(ISNUMBER(AG4),AG4,"")) | AU4: =IF(NOT(ISNUMBER(Q4)),"",Q4) -> 46220 | AW4: Completed | AX4: =IF(OR(AZ4="N/A",NOT(ISNUMBER(T4))),"",T4) -> 46224 | BA4: =IF(NOT(ISNUMBER(W4)),"",W4) -> 46225 | BD4: =IF(OR(Z4="",Z4="N/A"),"",IF(ISNUMBER(AU4),AU4,"")) | BI4: 46300 | BK4: =IF(NOT(ISNUMBER(BI4)),"",IF(WEEKDAY(BI4-CodeReviewCalendarDays,2)>5,BI4-CodeReviewCalendarDays-(WEEKDAY(BI4-CodeReviewCalendarDays,2)-5),BI4-CodeReviewCalendarDays)) -> 46297 | BM4: =IF(NOT(ISNUMBER(BK4)),"",IF(WEEKDAY(BK4-CodeReviewInviteCalendarDays,2)>5,BK4-CodeReviewInviteCalendarDays-(WEEKDAY(BK4-CodeReviewInviteCalendarDays,2)-5),BK4-CodeReviewInviteCalendarDays)) -> 46293 | BP4: =IF(A4="","",IF(IF(AND(ISNUMBER(J4),WEEKDAY(J4,2)<>2,WEEKDAY(J4,2)<>4)," | Release must be Tuesday or Thursday","")&IF(AND(ISNUMBER(H4),WEEKDAY(H4,2)<>1)," | Sprint Start is not a Monday - dates still calculated from the date entered","")&IF(AND(A4<>"",NOT(ISNUMBER(H4)),NOT(ISNUMBER(J4)))," | Enter Sprint Start or Release Date","")&IF(AND(ISNUMBER(F4),F4<TODAY(),D4<>"Completed")," | One or more raise-by dates are in the past and not completed","")&IF(AND(ISNUMBER(K4),K4-TODAY()<SprintWarningDays,K4>=TODAY(),OR(D4="Yet to start",D4="Blocked"))," | Sprint starts in under 10 days - raise access requests now","")&IF(AND(ISNUMBER(BM4),BN4<>"Completed",BN4<>"N/A",BM4-TODAY()<CodeReviewInviteCalendarDays)," | Code Review invite should be sent at least 4 days before Code Review","")="","",MID(IF(AND(ISNUMBER(J4),WEEKDAY(J4,2)<>2,WEEKDAY(J4,2)<>4)," | Release must be Tuesday or Thursday","")&IF(AND(ISNUMBER(H4),WEEKDAY(H4,2)<>1)," | Sprint Start is not a Monday - dates still calculated from the date entered","")&IF(AND(A4<>"",NOT(ISNUMBER(H4)),NOT(ISNUMBER(J4)))," | Enter Sprint Start or Release Date","")&IF(AND(ISNUMBER(F4),F4<TODAY(),D4<>"Completed")," | One or more raise-by dates are in the past and not completed","")&IF(AND(ISNUMBER(K4),K4-TODAY()<SprintWarningDays,K4>=TODAY(),OR(D4="Yet to start",D4="Blocked"))," | Sprint starts in under 10 days - raise access requests now","")&IF(AND(ISNUMBER(BM4),BN4<>"Completed",BN4<>"N/A",BM4-TODAY()<CodeReviewInviteCalendarDays)," | Code Review invite should be sent at least 4 days before Code Review",""),4,500))) -> Release must be Tuesday or Thursday | Sprint Start is not a Monday - dates still calculated from the date entered | One or more raise-by dates are in the past and not completed | BQ4: =IF(AND(ISNUMBER(Q4),S4<>"Completed",S4<>"N/A"),Q4,"") | BR4: =IF(AND(ISNUMBER(T4),V4<>"Completed",V4<>"N/A"),T4,"") | BS4: =IF(AND(ISNUMBER(W4),Y4<>"Completed",Y4<>"N/A"),W4,"") | BT4: =IF(AND(ISNUMBER(AA4),AC4<>"Completed",AC4<>"N/A"),AA4,"") | BU4: =IF(AND(ISNUMBER(AG4),AI4<>"Completed",AI4<>"N/A"),AG4,"") | BV4: =IF(AND(ISNUMBER(AJ4),AL4<>"Completed",AL4<>"N/A"),AJ4,"") | BW4: =IF(AND(ISNUMBER(AM4),AO4<>"Completed",AO4<>"N/A"),AM4,"") | BX4: =IF(AND(ISNUMBER(AP4),AR4<>"Completed",AR4<>"N/A"),AP4,"") | BY4: =IF(AND(ISNUMBER(AU4),AW4<>"Completed",AW4<>"N/A"),AU4,"") | BZ4: =IF(AND(ISNUMBER(AX4),AZ4<>"Completed",AZ4<>"N/A"),AX4,"") -> 46224 | CA4: =IF(AND(ISNUMBER(BA4),BC4<>"Completed",BC4<>"N/A"),BA4,"") -> 46225 | CB4: =IF(AND(ISNUMBER(BD4),BF4<>"Completed",BF4<>"N/A"),BD4,"") | CC4: =IF(AND(ISNUMBER(O4),P4<>"Completed",P4<>"N/A"),O4,"") | CD4: =IF(AND(ISNUMBER(BM4),BN4<>"Completed",BN4<>"N/A"),BM4,"") -> 46293 | CE4: =IF(AND(ISNUMBER(BK4),BL4<>"Completed",BL4<>"N/A"),BK4,"") -> 46297 | CF4: =IF(AND(ISNUMBER(BI4),BJ4<>"Completed",BJ4<>"N/A"),BI4,"") -> 46300 | CG4: =IF(OR(A4="",D4="Completed"),"",IF(N(G4)>0,1/(N(G4)+ROW()/100000),IF(ISNUMBER(F4),1000+F4+ROW()/100000,TODAY()+400+ROW()/100000))) -> 0.032258023
