Workbook
Name CABOffsetFromReleaseWD: Config!$B$8
Name CodeReviewCalendarDays: Config!$B$9
Name CodeReviewInviteCalendarDays: Config!$B$10
Name FileTypeList: Config!$G$3:$G$7
Name FrequencyList: Config!$H$3:$H$9
Name IAMList: Config!$I$3:$I$5
Name OUROffsetFromSR_WD: Config!$B$6
Name ReadyOffsetWD: Config!$B$4
Name RTSKOffsetFromOUR_WD: Config!$B$7
Name SprintCalendar: Sprints!$A$2:$C$12
Name SprintReadinessOffsetWD: Config!$B$15
Name SprintWarningDays: Config!$B$13
Name SprintWorkingDays: Config!$B$3
Name SROffsetFromStartWD: Config!$B$5
Name StatusList: Config!$E$3:$E$6
Name YesNoList: Config!$J$3:$J$4

Sheet Dashboard
B1: Application access & release tracker | I1: Formulas only. Update yellow cells on Tracker. Sheet is locked.
B2: As of | C2: =TODAY() | E2: Sprint calendar is on the Sprints sheet. File R-Task date copies the matching DB R-Task date. Overdue days grow until status is Completed. Enter Raised On when the ticket is submitted.
B4: Applications | D4: Overdue tickets | F4: Blocked | I4: Due in 7 days | K4: In progress | M4: Fully ready | O4: Worst overdue (days) | Q4: Raised on time
B5: =COUNTA(Tracker!A3:A70) | D5: =SUMPRODUCT((Tracker!$A$3:$A$70<>"")*(Tracker!$S$3:$S$70<>"Completed")*(ISNUMBER(Tracker!$Q$3:$Q$70))*(N(Tracker!$Q$3:$Q$70)<TODAY()))+SUMPRODUCT((Tracker!$A$3:$A$70<>"")*(Tracker!$V$3:$V$70<>"Completed")*(ISNUMBER(Tracker!$T$3:$T$70))*(N(Tracker!$T$3:$T$70)<TODAY()))+SUMPRODUCT((Tracker!$A$3:$A$70<>"")*(Tracker!$Y$3:$Y$70<>"Completed")*(ISNUMBER(Tracker!$W$3:$W$70))*(N(Tracker!$W$3:$W$70)<TODAY()))+SUMPRODUCT((Tracker!$A$3:$A$70<>"")*(Tracker!$AC$3:$AC$70<>"Completed")*(ISNUMBER(Tracker!$AA$3:$AA$70))*(N(Tracker!$AA$3:$AA$70)<TODAY()))+SUMPRODUCT((Tracker!$A$3:$A$70<>"")*(Tracker!$AI$3:$AI$70<>"Completed")*(ISNUMBER(Tracker!$AG$3:$AG$70))*(N(Tracker!$AG$3:$AG$70)<TODAY()))+SUMPRODUCT((Tracker!$A$3:$A$70<>"")*(Tracker!$AL$3:$AL$70<>"Completed")*(ISNUMBER(Tracker!$AJ$3:$AJ$70))*(N(Tracker!$AJ$3:$AJ$70)<TODAY()))+SUMPRODUCT((Tracker!$A$3:$A$70<>"")*(Tracker!$AO$3:$AO$70<>"Completed")*(ISNUMBER(Tracker!$AM$3:$AM$70))*(N(Tracker!$AM$3:$AM$70)<TODAY()))+SUMPRODUCT((Tracker!$A$3:$A$70<>"")*(Tracker!$AS$3:$AS$70<>"Completed")*(ISNUMBER(Tracker!$AQ$3:$AQ$70))*(N(Tracker!$AQ$3:$AQ$70)<TODAY()))+SUMPRODUCT((Tracker!$A$3:$A$70<>"")*(Tracker!$AY$3:$AY$70<>"Completed")*(ISNUMBER(Tracker!$AW$3:$AW$70))*(N(Tracker!$AW$3:$AW$70)<TODAY()))+SUMPRODUCT((Tracker!$A$3:$A$70<>"")*(Tracker!$BB$3:$BB$70<>"Completed")*(ISNUMBER(Tracker!$AZ$3:$AZ$70))*(N(Tracker!$AZ$3:$AZ$70)<TODAY()))+SUMPRODUCT((Tracker!$A$3:$A$70<>"")*(Tracker!$BE$3:$BE$70<>"Completed")*(ISNUMBER(Tracker!$BC$3:$BC$70))*(N(Tracker!$BC$3:$BC$70)<TODAY()))+SUMPRODUCT((Tracker!$A$3:$A$70<>"")*(Tracker!$BI$3:$BI$70<>"Completed")*(ISNUMBER(Tracker!$BG$3:$BG$70))*(N(Tracker!$BG$3:$BG$70)<TODAY()))+SUMPRODUCT((Tracker!$A$3:$A$70<>"")*(Tracker!$P$3:$P$70<>"Completed")*(ISNUMBER(Tracker!$O$3:$O$70))*(N(Tracker!$O$3:$O$70)<TODAY()))+SUMPRODUCT((Tracker!$A$3:$A$70<>"")*(Tracker!$BR$3:$BR$70<>"Completed")*(ISNUMBER(Tracker!$BQ$3:$BQ$70))*(N(Tracker!$BQ$3:$BQ$70)<TODAY()))+SUMPRODUCT((Tracker!$A$3:$A$70<>"")*(Tracker!$BP$3:$BP$70<>"Completed")*(ISNUMBER(Tracker!$BO$3:$BO$70))*(N(Tracker!$BO$3:$BO$70)<TODAY()))+SUMPRODUCT((Tracker!$A$3:$A$70<>"")*(Tracker!$BN$3:$BN$70<>"Completed")*(ISNUMBER(Tracker!$BM$3:$BM$70))*(N(Tracker!$BM$3:$BM$70)<TODAY())) | F5: =SUMPRODUCT((Tracker!$A$3:$A$70<>"")*(ISNUMBER(Tracker!$Q$3:$Q$70))*(Tracker!$S$3:$S$70="Blocked"))+SUMPRODUCT((Tracker!$A$3:$A$70<>"")*(ISNUMBER(Tracker!$T$3:$T$70))*(Tracker!$V$3:$V$70="Blocked"))+SUMPRODUCT((Tracker!$A$3:$A$70<>"")*(ISNUMBER(Tracker!$W$3:$W$70))*(Tracker!$Y$3:$Y$70="Blocked"))+SUMPRODUCT((Tracker!$A$3:$A$70<>"")*(ISNUMBER(Tracker!$AA$3:$AA$70))*(Tracker!$AC$3:$AC$70="Blocked"))+SUMPRODUCT((Tracker!$A$3:$A$70<>"")*(ISNUMBER(Tracker!$AG$3:$AG$70))*(Tracker!$AI$3:$AI$70="Blocked"))+SUMPRODUCT((Tracker!$A$3:$A$70<>"")*(ISNUMBER(Tracker!$AJ$3:$AJ$70))*(Tracker!$AL$3:$AL$70="Blocked"))+SUMPRODUCT((Tracker!$A$3:$A$70<>"")*(ISNUMBER(Tracker!$AM$3:$AM$70))*(Tracker!$AO$3:$AO$70="Blocked"))+SUMPRODUCT((Tracker!$A$3:$A$70<>"")*(ISNUMBER(Tracker!$AQ$3:$AQ$70))*(Tracker!$AS$3:$AS$70="Blocked"))+SUMPRODUCT((Tracker!$A$3:$A$70<>"")*(ISNUMBER(Tracker!$AW$3:$AW$70))*(Tracker!$AY$3:$AY$70="Blocked"))+SUMPRODUCT((Tracker!$A$3:$A$70<>"")*(ISNUMBER(Tracker!$AZ$3:$AZ$70))*(Tracker!$BB$3:$BB$70="Blocked"))+SUMPRODUCT((Tracker!$A$3:$A$70<>"")*(ISNUMBER(Tracker!$BC$3:$BC$70))*(Tracker!$BE$3:$BE$70="Blocked"))+SUMPRODUCT((Tracker!$A$3:$A$70<>"")*(ISNUMBER(Tracker!$BG$3:$BG$70))*(Tracker!$BI$3:$BI$70="Blocked"))+SUMPRODUCT((Tracker!$A$3:$A$70<>"")*(ISNUMBER(Tracker!$O$3:$O$70))*(Tracker!$P$3:$P$70="Blocked"))+SUMPRODUCT((Tracker!$A$3:$A$70<>"")*(ISNUMBER(Tracker!$BQ$3:$BQ$70))*(Tracker!$BR$3:$BR$70="Blocked"))+SUMPRODUCT((Tracker!$A$3:$A$70<>"")*(ISNUMBER(Tracker!$BO$3:$BO$70))*(Tracker!$BP$3:$BP$70="Blocked"))+SUMPRODUCT((Tracker!$A$3:$A$70<>"")*(ISNUMBER(Tracker!$BM$3:$BM$70))*(Tracker!$BN$3:$BN$70="Blocked")) | I5: =SUMPRODUCT((Tracker!$A$3:$A$70<>"")*(Tracker!$S$3:$S$70<>"Completed")*(ISNUMBER(Tracker!$Q$3:$Q$70))*(N(Tracker!$Q$3:$Q$70)>=TODAY())*(N(Tracker!$Q$3:$Q$70)<=TODAY()+7))+SUMPRODUCT((Tracker!$A$3:$A$70<>"")*(Tracker!$V$3:$V$70<>"Completed")*(ISNUMBER(Tracker!$T$3:$T$70))*(N(Tracker!$T$3:$T$70)>=TODAY())*(N(Tracker!$T$3:$T$70)<=TODAY()+7))+SUMPRODUCT((Tracker!$A$3:$A$70<>"")*(Tracker!$Y$3:$Y$70<>"Completed")*(ISNUMBER(Tracker!$W$3:$W$70))*(N(Tracker!$W$3:$W$70)>=TODAY())*(N(Tracker!$W$3:$W$70)<=TODAY()+7))+SUMPRODUCT((Tracker!$A$3:$A$70<>"")*(Tracker!$AC$3:$AC$70<>"Completed")*(ISNUMBER(Tracker!$AA$3:$AA$70))*(N(Tracker!$AA$3:$AA$70)>=TODAY())*(N(Tracker!$AA$3:$AA$70)<=TODAY()+7))+SUMPRODUCT((Tracker!$A$3:$A$70<>"")*(Tracker!$AI$3:$AI$70<>"Completed")*(ISNUMBER(Tracker!$AG$3:$AG$70))*(N(Tracker!$AG$3:$AG$70)>=TODAY())*(N(Tracker!$AG$3:$AG$70)<=TODAY()+7))+SUMPRODUCT((Tracker!$A$3:$A$70<>"")*(Tracker!$AL$3:$AL$70<>"Completed")*(ISNUMBER(Tracker!$AJ$3:$AJ$70))*(N(Tracker!$AJ$3:$AJ$70)>=TODAY())*(N(Tracker!$AJ$3:$AJ$70)<=TODAY()+7))+SUMPRODUCT((Tracker!$A$3:$A$70<>"")*(Tracker!$AO$3:$AO$70<>"Completed")*(ISNUMBER(Tracker!$AM$3:$AM$70))*(N(Tracker!$AM$3:$AM$70)>=TODAY())*(N(Tracker!$AM$3:$AM$70)<=TODAY()+7))+SUMPRODUCT((Tracker!$A$3:$A$70<>"")*(Tracker!$AS$3:$AS$70<>"Completed")*(ISNUMBER(Tracker!$AQ$3:$AQ$70))*(N(Tracker!$AQ$3:$AQ$70)>=TODAY())*(N(Tracker!$AQ$3:$AQ$70)<=TODAY()+7))+SUMPRODUCT((Tracker!$A$3:$A$70<>"")*(Tracker!$AY$3:$AY$70<>"Completed")*(ISNUMBER(Tracker!$AW$3:$AW$70))*(N(Tracker!$AW$3:$AW$70)>=TODAY())*(N(Tracker!$AW$3:$AW$70)<=TODAY()+7))+SUMPRODUCT((Tracker!$A$3:$A$70<>"")*(Tracker!$BB$3:$BB$70<>"Completed")*(ISNUMBER(Tracker!$AZ$3:$AZ$70))*(N(Tracker!$AZ$3:$AZ$70)>=TODAY())*(N(Tracker!$AZ$3:$AZ$70)<=TODAY()+7))+SUMPRODUCT((Tracker!$A$3:$A$70<>"")*(Tracker!$BE$3:$BE$70<>"Completed")*(ISNUMBER(Tracker!$BC$3:$BC$70))*(N(Tracker!$BC$3:$BC$70)>=TODAY())*(N(Tracker!$BC$3:$BC$70)<=TODAY()+7))+SUMPRODUCT((Tracker!$A$3:$A$70<>"")*(Tracker!$BI$3:$BI$70<>"Completed")*(ISNUMBER(Tracker!$BG$3:$BG$70))*(N(Tracker!$BG$3:$BG$70)>=TODAY())*(N(Tracker!$BG$3:$BG$70)<=TODAY()+7))+SUMPRODUCT((Tracker!$A$3:$A$70<>"")*(Tracker!$P$3:$P$70<>"Completed")*(ISNUMBER(Tracker!$O$3:$O$70))*(N(Tracker!$O$3:$O$70)>=TODAY())*(N(Tracker!$O$3:$O$70)<=TODAY()+7))+SUMPRODUCT((Tracker!$A$3:$A$70<>"")*(Tracker!$BR$3:$BR$70<>"Completed")*(ISNUMBER(Tracker!$BQ$3:$BQ$70))*(N(Tracker!$BQ$3:$BQ$70)>=TODAY())*(N(Tracker!$BQ$3:$BQ$70)<=TODAY()+7))+SUMPRODUCT((Tracker!$A$3:$A$70<>"")*(Tracker!$BP$3:$BP$70<>"Completed")*(ISNUMBER(Tracker!$BO$3:$BO$70))*(N(Tracker!$BO$3:$BO$70)>=TODAY())*(N(Tracker!$BO$3:$BO$70)<=TODAY()+7))+SUMPRODUCT((Tracker!$A$3:$A$70<>"")*(Tracker!$BN$3:$BN$70<>"Completed")*(ISNUMBER(Tracker!$BM$3:$BM$70))*(N(Tracker!$BM$3:$BM$70)>=TODAY())*(N(Tracker!$BM$3:$BM$70)<=TODAY()+7)) | K5: =SUMPRODUCT((Tracker!$A$3:$A$70<>"")*(ISNUMBER(Tracker!$Q$3:$Q$70))*(Tracker!$S$3:$S$70="In Progress"))+SUMPRODUCT((Tracker!$A$3:$A$70<>"")*(ISNUMBER(Tracker!$T$3:$T$70))*(Tracker!$V$3:$V$70="In Progress"))+SUMPRODUCT((Tracker!$A$3:$A$70<>"")*(ISNUMBER(Tracker!$W$3:$W$70))*(Tracker!$Y$3:$Y$70="In Progress"))+SUMPRODUCT((Tracker!$A$3:$A$70<>"")*(ISNUMBER(Tracker!$AA$3:$AA$70))*(Tracker!$AC$3:$AC$70="In Progress"))+SUMPRODUCT((Tracker!$A$3:$A$70<>"")*(ISNUMBER(Tracker!$AG$3:$AG$70))*(Tracker!$AI$3:$AI$70="In Progress"))+SUMPRODUCT((Tracker!$A$3:$A$70<>"")*(ISNUMBER(Tracker!$AJ$3:$AJ$70))*(Tracker!$AL$3:$AL$70="In Progress"))+SUMPRODUCT((Tracker!$A$3:$A$70<>"")*(ISNUMBER(Tracker!$AM$3:$AM$70))*(Tracker!$AO$3:$AO$70="In Progress"))+SUMPRODUCT((Tracker!$A$3:$A$70<>"")*(ISNUMBER(Tracker!$AQ$3:$AQ$70))*(Tracker!$AS$3:$AS$70="In Progress"))+SUMPRODUCT((Tracker!$A$3:$A$70<>"")*(ISNUMBER(Tracker!$AW$3:$AW$70))*(Tracker!$AY$3:$AY$70="In Progress"))+SUMPRODUCT((Tracker!$A$3:$A$70<>"")*(ISNUMBER(Tracker!$AZ$3:$AZ$70))*(Tracker!$BB$3:$BB$70="In Progress"))+SUMPRODUCT((Tracker!$A$3:$A$70<>"")*(ISNUMBER(Tracker!$BC$3:$BC$70))*(Tracker!$BE$3:$BE$70="In Progress"))+SUMPRODUCT((Tracker!$A$3:$A$70<>"")*(ISNUMBER(Tracker!$BG$3:$BG$70))*(Tracker!$BI$3:$BI$70="In Progress"))+SUMPRODUCT((Tracker!$A$3:$A$70<>"")*(ISNUMBER(Tracker!$O$3:$O$70))*(Tracker!$P$3:$P$70="In Progress"))+SUMPRODUCT((Tracker!$A$3:$A$70<>"")*(ISNUMBER(Tracker!$BQ$3:$BQ$70))*(Tracker!$BR$3:$BR$70="In Progress"))+SUMPRODUCT((Tracker!$A$3:$A$70<>"")*(ISNUMBER(Tracker!$BO$3:$BO$70))*(Tracker!$BP$3:$BP$70="In Progress"))+SUMPRODUCT((Tracker!$A$3:$A$70<>"")*(ISNUMBER(Tracker!$BM$3:$BM$70))*(Tracker!$BN$3:$BN$70="In Progress")) | M5: =COUNTIF(Tracker!D3:D70,"Completed") | O5: =IFERROR(MAX(Tracker!G3:G70),0) | Q5: =SUMPRODUCT((Tracker!$A$3:$A$70<>"")*(ISNUMBER(Tracker!$Q$3:$Q$70))*(ISNUMBER(Tracker!$R$3:$R$70))*(N(Tracker!$R$3:$R$70)<=N(Tracker!$Q$3:$Q$70)))+SUMPRODUCT((Tracker!$A$3:$A$70<>"")*(ISNUMBER(Tracker!$T$3:$T$70))*(ISNUMBER(Tracker!$U$3:$U$70))*(N(Tracker!$U$3:$U$70)<=N(Tracker!$T$3:$T$70)))+SUMPRODUCT((Tracker!$A$3:$A$70<>"")*(ISNUMBER(Tracker!$W$3:$W$70))*(ISNUMBER(Tracker!$X$3:$X$70))*(N(Tracker!$X$3:$X$70)<=N(Tracker!$W$3:$W$70)))+SUMPRODUCT((Tracker!$A$3:$A$70<>"")*(ISNUMBER(Tracker!$AA$3:$AA$70))*(ISNUMBER(Tracker!$AB$3:$AB$70))*(N(Tracker!$AB$3:$AB$70)<=N(Tracker!$AA$3:$AA$70)))+SUMPRODUCT((Tracker!$A$3:$A$70<>"")*(ISNUMBER(Tracker!$AG$3:$AG$70))*(ISNUMBER(Tracker!$AH$3:$AH$70))*(N(Tracker!$AH$3:$AH$70)<=N(Tracker!$AG$3:$AG$70)))+SUMPRODUCT((Tracker!$A$3:$A$70<>"")*(ISNUMBER(Tracker!$AJ$3:$AJ$70))*(ISNUMBER(Tracker!$AK$3:$AK$70))*(N(Tracker!$AK$3:$AK$70)<=N(Tracker!$AJ$3:$AJ$70)))+SUMPRODUCT((Tracker!$A$3:$A$70<>"")*(ISNUMBER(Tracker!$AM$3:$AM$70))*(ISNUMBER(Tracker!$AN$3:$AN$70))*(N(Tracker!$AN$3:$AN$70)<=N(Tracker!$AM$3:$AM$70)))+SUMPRODUCT((Tracker!$A$3:$A$70<>"")*(ISNUMBER(Tracker!$AQ$3:$AQ$70))*(ISNUMBER(Tracker!$AR$3:$AR$70))*(N(Tracker!$AR$3:$AR$70)<=N(Tracker!$AQ$3:$AQ$70)))+SUMPRODUCT((Tracker!$A$3:$A$70<>"")*(ISNUMBER(Tracker!$AW$3:$AW$70))*(ISNUMBER(Tracker!$AX$3:$AX$70))*(N(Tracker!$AX$3:$AX$70)<=N(Tracker!$AW$3:$AW$70)))+SUMPRODUCT((Tracker!$A$3:$A$70<>"")*(ISNUMBER(Tracker!$AZ$3:$AZ$70))*(ISNUMBER(Tracker!$BA$3:$BA$70))*(N(Tracker!$BA$3:$BA$70)<=N(Tracker!$AZ$3:$AZ$70)))+SUMPRODUCT((Tracker!$A$3:$A$70<>"")*(ISNUMBER(Tracker!$BC$3:$BC$70))*(ISNUMBER(Tracker!$BD$3:$BD$70))*(N(Tracker!$BD$3:$BD$70)<=N(Tracker!$BC$3:$BC$70)))+SUMPRODUCT((Tracker!$A$3:$A$70<>"")*(ISNUMBER(Tracker!$BG$3:$BG$70))*(ISNUMBER(Tracker!$BH$3:$BH$70))*(N(Tracker!$BH$3:$BH$70)<=N(Tracker!$BG$3:$BG$70)))
B6: Apps with a name filled | D6: Date in the past and status not Completed | F6: Requests marked Blocked | I6: Raise-by in the next week, not Completed | K6: Tickets marked In Progress | M6: Every dated request Completed | O6: Days past raise-by among open requests. Increases daily until Completed. | Q6: Requests with Raised On filled on or before the raise-by date.
B8: Apps overdue - worst first (days overdue keeps increasing until Completed) | I8: Where work is stuck - by request type
B9: Application | C9: Sprint | D9: Overall Status | E9: Next Action | F9: Next Action Date | G9: Days overdue | I9: Request type | J9: Overdue | K9: Due in 7 days | L9: Blocked | M9: In Progress | N9: Pending | O9: Completed | P9: Overdue bar
B10: =IFERROR(INDEX(Tracker!$A$3:$A$70,MATCH(_xludf.AGGREGATE(15,6,Tracker!$CK$3:$CK$70,1),Tracker!$CK$3:$CK$70,0)),"") | C10: =IF(B10="","",IFERROR(INDEX(Tracker!$C$3:$C$70,MATCH(_xludf.AGGREGATE(15,6,Tracker!$CK$3:$CK$70,1),Tracker!$CK$3:$CK$70,0)),"")) | D10: =IF(B10="","",IFERROR(INDEX(Tracker!$D$3:$D$70,MATCH(_xludf.AGGREGATE(15,6,Tracker!$CK$3:$CK$70,1),Tracker!$CK$3:$CK$70,0)),"")) | E10: =IF(B10="","",IFERROR(INDEX(Tracker!$E$3:$E$70,MATCH(_xludf.AGGREGATE(15,6,Tracker!$CK$3:$CK$70,1),Tracker!$CK$3:$CK$70,0)),"")) | F10: =IF(B10="","",IFERROR(INDEX(Tracker!$F$3:$F$70,MATCH(_xludf.AGGREGATE(15,6,Tracker!$CK$3:$CK$70,1),Tracker!$CK$3:$CK$70,0)),"")) | G10: =IF(B10="","",IFERROR(INDEX(Tracker!$G$3:$G$70,MATCH(_xludf.AGGREGATE(15,6,Tracker!$CK$3:$CK$70,1),Tracker!$CK$3:$CK$70,0)),"")) | I10: Dev R-Task | J10: =SUMPRODUCT((Tracker!$A$3:$A$70<>"")*(Tracker!$S$3:$S$70<>"Completed")*(ISNUMBER(Tracker!$Q$3:$Q$70))*(N(Tracker!$Q$3:$Q$70)<TODAY())) | K10: =SUMPRODUCT((Tracker!$A$3:$A$70<>"")*(Tracker!$S$3:$S$70<>"Completed")*(ISNUMBER(Tracker!$Q$3:$Q$70))*(N(Tracker!$Q$3:$Q$70)>=TODAY())*(N(Tracker!$Q$3:$Q$70)<=TODAY()+7)) | L10: =SUMPRODUCT((Tracker!$A$3:$A$70<>"")*(ISNUMBER(Tracker!$Q$3:$Q$70))*(Tracker!$S$3:$S$70="Blocked")) | M10: =SUMPRODUCT((Tracker!$A$3:$A$70<>"")*(ISNUMBER(Tracker!$Q$3:$Q$70))*(Tracker!$S$3:$S$70="In Progress")) | N10: =SUMPRODUCT((Tracker!$A$3:$A$70<>"")*(ISNUMBER(Tracker!$M$3:$M$70))*(Tracker!$N$3:$N$70<>"Completed")*(Tracker!$N$3:$N$70<>"Blocked")*(Tracker!$N$3:$N$70<>"In Progress")) | O10: =SUMPRODUCT((Tracker!$A$3:$A$70<>"")*(ISNUMBER(Tracker!$M$3:$M$70))*(Tracker!$N$3:$N$70="Completed")) | P10: =IF(N(J10)<=0,"",REPT("|",MIN(N(J10),25)))
B11: =IFERROR(INDEX(Tracker!$A$3:$A$70,MATCH(_xludf.AGGREGATE(15,6,Tracker!$CK$3:$CK$70,2),Tracker!$CK$3:$CK$70,0)),"") | C11: =IF(B11="","",IFERROR(INDEX(Tracker!$C$3:$C$70,MATCH(_xludf.AGGREGATE(15,6,Tracker!$CK$3:$CK$70,2),Tracker!$CK$3:$CK$70,0)),"")) | D11: =IF(B11="","",IFERROR(INDEX(Tracker!$D$3:$D$70,MATCH(_xludf.AGGREGATE(15,6,Tracker!$CK$3:$CK$70,2),Tracker!$CK$3:$CK$70,0)),"")) | E11: =IF(B11="","",IFERROR(INDEX(Tracker!$E$3:$E$70,MATCH(_xludf.AGGREGATE(15,6,Tracker!$CK$3:$CK$70,2),Tracker!$CK$3:$CK$70,0)),"")) | F11: =IF(B11="","",IFERROR(INDEX(Tracker!$F$3:$F$70,MATCH(_xludf.AGGREGATE(15,6,Tracker!$CK$3:$CK$70,2),Tracker!$CK$3:$CK$70,0)),"")) | G11: =IF(B11="","",IFERROR(INDEX(Tracker!$G$3:$G$70,MATCH(_xludf.AGGREGATE(15,6,Tracker!$CK$3:$CK$70,2),Tracker!$CK$3:$CK$70,0)),"")) | I11: Dev OUR | J11: =SUMPRODUCT((Tracker!$A$3:$A$70<>"")*(Tracker!$V$3:$V$70<>"Completed")*(ISNUMBER(Tracker!$T$3:$T$70))*(N(Tracker!$T$3:$T$70)<TODAY())) | K11: =SUMPRODUCT((Tracker!$A$3:$A$70<>"")*(Tracker!$V$3:$V$70<>"Completed")*(ISNUMBER(Tracker!$T$3:$T$70))*(N(Tracker!$T$3:$T$70)>=TODAY())*(N(Tracker!$T$3:$T$70)<=TODAY()+7)) | L11: =SUMPRODUCT((Tracker!$A$3:$A$70<>"")*(ISNUMBER(Tracker!$T$3:$T$70))*(Tracker!$V$3:$V$70="Blocked")) | M11: =SUMPRODUCT((Tracker!$A$3:$A$70<>"")*(ISNUMBER(Tracker!$T$3:$T$70))*(Tracker!$V$3:$V$70="In Progress")) | N11: =SUMPRODUCT((Tracker!$A$3:$A$70<>"")*(ISNUMBER(Tracker!$O$3:$O$70))*(Tracker!$P$3:$P$70<>"Completed")*(Tracker!$P$3:$P$70<>"Blocked")*(Tracker!$P$3:$P$70<>"In Progress")) | O11: =SUMPRODUCT((Tracker!$A$3:$A$70<>"")*(ISNUMBER(Tracker!$O$3:$O$70))*(Tracker!$P$3:$P$70="Completed")) | P11: =IF(N(J11)<=0,"",REPT("|",MIN(N(J11),25)))
B12: =IFERROR(INDEX(Tracker!$A$3:$A$70,MATCH(_xludf.AGGREGATE(15,6,Tracker!$CK$3:$CK$70,3),Tracker!$CK$3:$CK$70,0)),"") | C12: =IF(B12="","",IFERROR(INDEX(Tracker!$C$3:$C$70,MATCH(_xludf.AGGREGATE(15,6,Tracker!$CK$3:$CK$70,3),Tracker!$CK$3:$CK$70,0)),"")) | D12: =IF(B12="","",IFERROR(INDEX(Tracker!$D$3:$D$70,MATCH(_xludf.AGGREGATE(15,6,Tracker!$CK$3:$CK$70,3),Tracker!$CK$3:$CK$70,0)),"")) | E12: =IF(B12="","",IFERROR(INDEX(Tracker!$E$3:$E$70,MATCH(_xludf.AGGREGATE(15,6,Tracker!$CK$3:$CK$70,3),Tracker!$CK$3:$CK$70,0)),"")) | F12: =IF(B12="","",IFERROR(INDEX(Tracker!$F$3:$F$70,MATCH(_xludf.AGGREGATE(15,6,Tracker!$CK$3:$CK$70,3),Tracker!$CK$3:$CK$70,0)),"")) | G12: =IF(B12="","",IFERROR(INDEX(Tracker!$G$3:$G$70,MATCH(_xludf.AGGREGATE(15,6,Tracker!$CK$3:$CK$70,3),Tracker!$CK$3:$CK$70,0)),"")) | I12: Dev Service Request | J12: =SUMPRODUCT((Tracker!$A$3:$A$70<>"")*(Tracker!$Y$3:$Y$70<>"Completed")*(ISNUMBER(Tracker!$W$3:$W$70))*(N(Tracker!$W$3:$W$70)<TODAY())) | K12: =SUMPRODUCT((Tracker!$A$3:$A$70<>"")*(Tracker!$Y$3:$Y$70<>"Completed")*(ISNUMBER(Tracker!$W$3:$W$70))*(N(Tracker!$W$3:$W$70)>=TODAY())*(N(Tracker!$W$3:$W$70)<=TODAY()+7)) | L12: =SUMPRODUCT((Tracker!$A$3:$A$70<>"")*(ISNUMBER(Tracker!$W$3:$W$70))*(Tracker!$Y$3:$Y$70="Blocked")) | M12: =SUMPRODUCT((Tracker!$A$3:$A$70<>"")*(ISNUMBER(Tracker!$W$3:$W$70))*(Tracker!$Y$3:$Y$70="In Progress")) | N12: =SUMPRODUCT((Tracker!$A$3:$A$70<>"")*(ISNUMBER(Tracker!$Q$3:$Q$70))*(Tracker!$R$3:$R$70<>"Completed")*(Tracker!$R$3:$R$70<>"Blocked")*(Tracker!$R$3:$R$70<>"In Progress")) | O12: =SUMPRODUCT((Tracker!$A$3:$A$70<>"")*(ISNUMBER(Tracker!$Q$3:$Q$70))*(Tracker!$R$3:$R$70="Completed")) | P12: =IF(N(J12)<=0,"",REPT("|",MIN(N(J12),25)))
B13: =IFERROR(INDEX(Tracker!$A$3:$A$70,MATCH(_xludf.AGGREGATE(15,6,Tracker!$CK$3:$CK$70,4),Tracker!$CK$3:$CK$70,0)),"") | C13: =IF(B13="","",IFERROR(INDEX(Tracker!$C$3:$C$70,MATCH(_xludf.AGGREGATE(15,6,Tracker!$CK$3:$CK$70,4),Tracker!$CK$3:$CK$70,0)),"")) | D13: =IF(B13="","",IFERROR(INDEX(Tracker!$D$3:$D$70,MATCH(_xludf.AGGREGATE(15,6,Tracker!$CK$3:$CK$70,4),Tracker!$CK$3:$CK$70,0)),"")) | E13: =IF(B13="","",IFERROR(INDEX(Tracker!$E$3:$E$70,MATCH(_xludf.AGGREGATE(15,6,Tracker!$CK$3:$CK$70,4),Tracker!$CK$3:$CK$70,0)),"")) | F13: =IF(B13="","",IFERROR(INDEX(Tracker!$F$3:$F$70,MATCH(_xludf.AGGREGATE(15,6,Tracker!$CK$3:$CK$70,4),Tracker!$CK$3:$CK$70,0)),"")) | G13: =IF(B13="","",IFERROR(INDEX(Tracker!$G$3:$G$70,MATCH(_xludf.AGGREGATE(15,6,Tracker!$CK$3:$CK$70,4),Tracker!$CK$3:$CK$70,0)),"")) | I13: QA R-Task | J13: =SUMPRODUCT((Tracker!$A$3:$A$70<>"")*(Tracker!$AI$3:$AI$70<>"Completed")*(ISNUMBER(Tracker!$AG$3:$AG$70))*(N(Tracker!$AG$3:$AG$70)<TODAY())) | K13: =SUMPRODUCT((Tracker!$A$3:$A$70<>"")*(Tracker!$AI$3:$AI$70<>"Completed")*(ISNUMBER(Tracker!$AG$3:$AG$70))*(N(Tracker!$AG$3:$AG$70)>=TODAY())*(N(Tracker!$AG$3:$AG$70)<=TODAY()+7)) | L13: =SUMPRODUCT((Tracker!$A$3:$A$70<>"")*(ISNUMBER(Tracker!$AG$3:$AG$70))*(Tracker!$AI$3:$AI$70="Blocked")) | M13: =SUMPRODUCT((Tracker!$A$3:$A$70<>"")*(ISNUMBER(Tracker!$AG$3:$AG$70))*(Tracker!$AI$3:$AI$70="In Progress")) | N13: =SUMPRODUCT((Tracker!$A$3:$A$70<>"")*(ISNUMBER(Tracker!$S$3:$S$70))*(Tracker!$T$3:$T$70<>"Completed")*(Tracker!$T$3:$T$70<>"Blocked")*(Tracker!$T$3:$T$70<>"In Progress")) | O13: =SUMPRODUCT((Tracker!$A$3:$A$70<>"")*(ISNUMBER(Tracker!$S$3:$S$70))*(Tracker!$T$3:$T$70="Completed")) | P13: =IF(N(J13)<=0,"",REPT("|",MIN(N(J13),25)))
B14: =IFERROR(INDEX(Tracker!$A$3:$A$70,MATCH(_xludf.AGGREGATE(15,6,Tracker!$CK$3:$CK$70,5),Tracker!$CK$3:$CK$70,0)),"") | C14: =IF(B14="","",IFERROR(INDEX(Tracker!$C$3:$C$70,MATCH(_xludf.AGGREGATE(15,6,Tracker!$CK$3:$CK$70,5),Tracker!$CK$3:$CK$70,0)),"")) | D14: =IF(B14="","",IFERROR(INDEX(Tracker!$D$3:$D$70,MATCH(_xludf.AGGREGATE(15,6,Tracker!$CK$3:$CK$70,5),Tracker!$CK$3:$CK$70,0)),"")) | E14: =IF(B14="","",IFERROR(INDEX(Tracker!$E$3:$E$70,MATCH(_xludf.AGGREGATE(15,6,Tracker!$CK$3:$CK$70,5),Tracker!$CK$3:$CK$70,0)),"")) | F14: =IF(B14="","",IFERROR(INDEX(Tracker!$F$3:$F$70,MATCH(_xludf.AGGREGATE(15,6,Tracker!$CK$3:$CK$70,5),Tracker!$CK$3:$CK$70,0)),"")) | G14: =IF(B14="","",IFERROR(INDEX(Tracker!$G$3:$G$70,MATCH(_xludf.AGGREGATE(15,6,Tracker!$CK$3:$CK$70,5),Tracker!$CK$3:$CK$70,0)),"")) | I14: QA OUR | J14: =SUMPRODUCT((Tracker!$A$3:$A$70<>"")*(Tracker!$AL$3:$AL$70<>"Completed")*(ISNUMBER(Tracker!$AJ$3:$AJ$70))*(N(Tracker!$AJ$3:$AJ$70)<TODAY())) | K14: =SUMPRODUCT((Tracker!$A$3:$A$70<>"")*(Tracker!$AL$3:$AL$70<>"Completed")*(ISNUMBER(Tracker!$AJ$3:$AJ$70))*(N(Tracker!$AJ$3:$AJ$70)>=TODAY())*(N(Tracker!$AJ$3:$AJ$70)<=TODAY()+7)) | L14: =SUMPRODUCT((Tracker!$A$3:$A$70<>"")*(ISNUMBER(Tracker!$AJ$3:$AJ$70))*(Tracker!$AL$3:$AL$70="Blocked")) | M14: =SUMPRODUCT((Tracker!$A$3:$A$70<>"")*(ISNUMBER(Tracker!$AJ$3:$AJ$70))*(Tracker!$AL$3:$AL$70="In Progress")) | N14: =SUMPRODUCT((Tracker!$A$3:$A$70<>"")*(ISNUMBER(Tracker!$U$3:$U$70))*(Tracker!$V$3:$V$70<>"Completed")*(Tracker!$V$3:$V$70<>"Blocked")*(Tracker!$V$3:$V$70<>"In Progress")) | O14: =SUMPRODUCT((Tracker!$A$3:$A$70<>"")*(ISNUMBER(Tracker!$U$3:$U$70))*(Tracker!$V$3:$V$70="Completed")) | P14: =IF(N(J14)<=0,"",REPT("|",MIN(N(J14),25)))
B15: =IFERROR(INDEX(Tracker!$A$3:$A$70,MATCH(_xludf.AGGREGATE(15,6,Tracker!$CK$3:$CK$70,6),Tracker!$CK$3:$CK$70,0)),"") | C15: =IF(B15="","",IFERROR(INDEX(Tracker!$C$3:$C$70,MATCH(_xludf.AGGREGATE(15,6,Tracker!$CK$3:$CK$70,6),Tracker!$CK$3:$CK$70,0)),"")) | D15: =IF(B15="","",IFERROR(INDEX(Tracker!$D$3:$D$70,MATCH(_xludf.AGGREGATE(15,6,Tracker!$CK$3:$CK$70,6),Tracker!$CK$3:$CK$70,0)),"")) | E15: =IF(B15="","",IFERROR(INDEX(Tracker!$E$3:$E$70,MATCH(_xludf.AGGREGATE(15,6,Tracker!$CK$3:$CK$70,6),Tracker!$CK$3:$CK$70,0)),"")) | F15: =IF(B15="","",IFERROR(INDEX(Tracker!$F$3:$F$70,MATCH(_xludf.AGGREGATE(15,6,Tracker!$CK$3:$CK$70,6),Tracker!$CK$3:$CK$70,0)),"")) | G15: =IF(B15="","",IFERROR(INDEX(Tracker!$G$3:$G$70,MATCH(_xludf.AGGREGATE(15,6,Tracker!$CK$3:$CK$70,6),Tracker!$CK$3:$CK$70,0)),"")) | I15: QA Service Request | J15: =SUMPRODUCT((Tracker!$A$3:$A$70<>"")*(Tracker!$AO$3:$AO$70<>"Completed")*(ISNUMBER(Tracker!$AM$3:$AM$70))*(N(Tracker!$AM$3:$AM$70)<TODAY())) | K15: =SUMPRODUCT((Tracker!$A$3:$A$70<>"")*(Tracker!$AO$3:$AO$70<>"Completed")*(ISNUMBER(Tracker!$AM$3:$AM$70))*(N(Tracker!$AM$3:$AM$70)>=TODAY())*(N(Tracker!$AM$3:$AM$70)<=TODAY()+7)) | L15: =SUMPRODUCT((Tracker!$A$3:$A$70<>"")*(ISNUMBER(Tracker!$AM$3:$AM$70))*(Tracker!$AO$3:$AO$70="Blocked")) | M15: =SUMPRODUCT((Tracker!$A$3:$A$70<>"")*(ISNUMBER(Tracker!$AM$3:$AM$70))*(Tracker!$AO$3:$AO$70="In Progress")) | N15: =SUMPRODUCT((Tracker!$A$3:$A$70<>"")*(ISNUMBER(Tracker!$W$3:$W$70))*(Tracker!$X$3:$X$70<>"Completed")*(Tracker!$X$3:$X$70<>"Blocked")*(Tracker!$X$3:$X$70<>"In Progress")) | O15: =SUMPRODUCT((Tracker!$A$3:$A$70<>"")*(ISNUMBER(Tracker!$W$3:$W$70))*(Tracker!$X$3:$X$70="Completed")) | P15: =IF(N(J15)<=0,"",REPT("|",MIN(N(J15),25)))
B16: =IFERROR(INDEX(Tracker!$A$3:$A$70,MATCH(_xludf.AGGREGATE(15,6,Tracker!$CK$3:$CK$70,7),Tracker!$CK$3:$CK$70,0)),"") | C16: =IF(B16="","",IFERROR(INDEX(Tracker!$C$3:$C$70,MATCH(_xludf.AGGREGATE(15,6,Tracker!$CK$3:$CK$70,7),Tracker!$CK$3:$CK$70,0)),"")) | D16: =IF(B16="","",IFERROR(INDEX(Tracker!$D$3:$D$70,MATCH(_xludf.AGGREGATE(15,6,Tracker!$CK$3:$CK$70,7),Tracker!$CK$3:$CK$70,0)),"")) | E16: =IF(B16="","",IFERROR(INDEX(Tracker!$E$3:$E$70,MATCH(_xludf.AGGREGATE(15,6,Tracker!$CK$3:$CK$70,7),Tracker!$CK$3:$CK$70,0)),"")) | F16: =IF(B16="","",IFERROR(INDEX(Tracker!$F$3:$F$70,MATCH(_xludf.AGGREGATE(15,6,Tracker!$CK$3:$CK$70,7),Tracker!$CK$3:$CK$70,0)),"")) | G16: =IF(B16="","",IFERROR(INDEX(Tracker!$G$3:$G$70,MATCH(_xludf.AGGREGATE(15,6,Tracker!$CK$3:$CK$70,7),Tracker!$CK$3:$CK$70,0)),"")) | I16: Prod R-Task | J16: =SUMPRODUCT((Tracker!$A$3:$A$70<>"")*(Tracker!$AY$3:$AY$70<>"Completed")*(ISNUMBER(Tracker!$AW$3:$AW$70))*(N(Tracker!$AW$3:$AW$70)<TODAY())) | K16: =SUMPRODUCT((Tracker!$A$3:$A$70<>"")*(Tracker!$AY$3:$AY$70<>"Completed")*(ISNUMBER(Tracker!$AW$3:$AW$70))*(N(Tracker!$AW$3:$AW$70)>=TODAY())*(N(Tracker!$AW$3:$AW$70)<=TODAY()+7)) | L16: =SUMPRODUCT((Tracker!$A$3:$A$70<>"")*(ISNUMBER(Tracker!$AW$3:$AW$70))*(Tracker!$AY$3:$AY$70="Blocked")) | M16: =SUMPRODUCT((Tracker!$A$3:$A$70<>"")*(ISNUMBER(Tracker!$AW$3:$AW$70))*(Tracker!$AY$3:$AY$70="In Progress")) | N16: =SUMPRODUCT((Tracker!$A$3:$A$70<>"")*(ISNUMBER(Tracker!$Y$3:$Y$70))*(Tracker!$Z$3:$Z$70<>"Completed")*(Tracker!$Z$3:$Z$70<>"Blocked")*(Tracker!$Z$3:$Z$70<>"In Progress")) | O16: =SUMPRODUCT((Tracker!$A$3:$A$70<>"")*(ISNUMBER(Tracker!$Y$3:$Y$70))*(Tracker!$Z$3:$Z$70="Completed")) | P16: =IF(N(J16)<=0,"",REPT("|",MIN(N(J16),25)))
B17: =IFERROR(INDEX(Tracker!$A$3:$A$70,MATCH(_xludf.AGGREGATE(15,6,Tracker!$CK$3:$CK$70,8),Tracker!$CK$3:$CK$70,0)),"") | C17: =IF(B17="","",IFERROR(INDEX(Tracker!$C$3:$C$70,MATCH(_xludf.AGGREGATE(15,6,Tracker!$CK$3:$CK$70,8),Tracker!$CK$3:$CK$70,0)),"")) | D17: =IF(B17="","",IFERROR(INDEX(Tracker!$D$3:$D$70,MATCH(_xludf.AGGREGATE(15,6,Tracker!$CK$3:$CK$70,8),Tracker!$CK$3:$CK$70,0)),"")) | E17: =IF(B17="","",IFERROR(INDEX(Tracker!$E$3:$E$70,MATCH(_xludf.AGGREGATE(15,6,Tracker!$CK$3:$CK$70,8),Tracker!$CK$3:$CK$70,0)),"")) | F17: =IF(B17="","",IFERROR(INDEX(Tracker!$F$3:$F$70,MATCH(_xludf.AGGREGATE(15,6,Tracker!$CK$3:$CK$70,8),Tracker!$CK$3:$CK$70,0)),"")) | G17: =IF(B17="","",IFERROR(INDEX(Tracker!$G$3:$G$70,MATCH(_xludf.AGGREGATE(15,6,Tracker!$CK$3:$CK$70,8),Tracker!$CK$3:$CK$70,0)),"")) | I17: Prod OUR | J17: =SUMPRODUCT((Tracker!$A$3:$A$70<>"")*(Tracker!$BB$3:$BB$70<>"Completed")*(ISNUMBER(Tracker!$AZ$3:$AZ$70))*(N(Tracker!$AZ$3:$AZ$70)<TODAY())) | K17: =SUMPRODUCT((Tracker!$A$3:$A$70<>"")*(Tracker!$BB$3:$BB$70<>"Completed")*(ISNUMBER(Tracker!$AZ$3:$AZ$70))*(N(Tracker!$AZ$3:$AZ$70)>=TODAY())*(N(Tracker!$AZ$3:$AZ$70)<=TODAY()+7)) | L17: =SUMPRODUCT((Tracker!$A$3:$A$70<>"")*(ISNUMBER(Tracker!$AZ$3:$AZ$70))*(Tracker!$BB$3:$BB$70="Blocked")) | M17: =SUMPRODUCT((Tracker!$A$3:$A$70<>"")*(ISNUMBER(Tracker!$AZ$3:$AZ$70))*(Tracker!$BB$3:$BB$70="In Progress")) | N17: =SUMPRODUCT((Tracker!$A$3:$A$70<>"")*(ISNUMBER(Tracker!$AA$3:$AA$70))*(Tracker!$AB$3:$AB$70<>"Completed")*(Tracker!$AB$3:$AB$70<>"Blocked")*(Tracker!$AB$3:$AB$70<>"In Progress")) | O17: =SUMPRODUCT((Tracker!$A$3:$A$70<>"")*(ISNUMBER(Tracker!$AA$3:$AA$70))*(Tracker!$AB$3:$AB$70="Completed")) | P17: =IF(N(J17)<=0,"",REPT("|",MIN(N(J17),25)))
B18: =IFERROR(INDEX(Tracker!$A$3:$A$70,MATCH(_xludf.AGGREGATE(15,6,Tracker!$CK$3:$CK$70,9),Tracker!$CK$3:$CK$70,0)),"") | C18: =IF(B18="","",IFERROR(INDEX(Tracker!$C$3:$C$70,MATCH(_xludf.AGGREGATE(15,6,Tracker!$CK$3:$CK$70,9),Tracker!$CK$3:$CK$70,0)),"")) | D18: =IF(B18="","",IFERROR(INDEX(Tracker!$D$3:$D$70,MATCH(_xludf.AGGREGATE(15,6,Tracker!$CK$3:$CK$70,9),Tracker!$CK$3:$CK$70,0)),"")) | E18: =IF(B18="","",IFERROR(INDEX(Tracker!$E$3:$E$70,MATCH(_xludf.AGGREGATE(15,6,Tracker!$CK$3:$CK$70,9),Tracker!$CK$3:$CK$70,0)),"")) | F18: =IF(B18="","",IFERROR(INDEX(Tracker!$F$3:$F$70,MATCH(_xludf.AGGREGATE(15,6,Tracker!$CK$3:$CK$70,9),Tracker!$CK$3:$CK$70,0)),"")) | G18: =IF(B18="","",IFERROR(INDEX(Tracker!$G$3:$G$70,MATCH(_xludf.AGGREGATE(15,6,Tracker!$CK$3:$CK$70,9),Tracker!$CK$3:$CK$70,0)),"")) | I18: Prod Service Request | J18: =SUMPRODUCT((Tracker!$A$3:$A$70<>"")*(Tracker!$BE$3:$BE$70<>"Completed")*(ISNUMBER(Tracker!$BC$3:$BC$70))*(N(Tracker!$BC$3:$BC$70)<TODAY())) | K18: =SUMPRODUCT((Tracker!$A$3:$A$70<>"")*(Tracker!$BE$3:$BE$70<>"Completed")*(ISNUMBER(Tracker!$BC$3:$BC$70))*(N(Tracker!$BC$3:$BC$70)>=TODAY())*(N(Tracker!$BC$3:$BC$70)<=TODAY()+7)) | L18: =SUMPRODUCT((Tracker!$A$3:$A$70<>"")*(ISNUMBER(Tracker!$BC$3:$BC$70))*(Tracker!$BE$3:$BE$70="Blocked")) | M18: =SUMPRODUCT((Tracker!$A$3:$A$70<>"")*(ISNUMBER(Tracker!$BC$3:$BC$70))*(Tracker!$BE$3:$BE$70="In Progress")) | N18: =SUMPRODUCT((Tracker!$A$3:$A$70<>"")*(ISNUMBER(Tracker!$AC$3:$AC$70))*(Tracker!$AD$3:$AD$70<>"Completed")*(Tracker!$AD$3:$AD$70<>"Blocked")*(Tracker!$AD$3:$AD$70<>"In Progress")) | O18: =SUMPRODUCT((Tracker!$A$3:$A$70<>"")*(ISNUMBER(Tracker!$AC$3:$AC$70))*(Tracker!$AD$3:$AD$70="Completed")) | P18: =IF(N(J18)<=0,"",REPT("|",MIN(N(J18),25)))
B19: =IFERROR(INDEX(Tracker!$A$3:$A$70,MATCH(_xludf.AGGREGATE(15,6,Tracker!$CK$3:$CK$70,10),Tracker!$CK$3:$CK$70,0)),"") | C19: =IF(B19="","",IFERROR(INDEX(Tracker!$C$3:$C$70,MATCH(_xludf.AGGREGATE(15,6,Tracker!$CK$3:$CK$70,10),Tracker!$CK$3:$CK$70,0)),"")) | D19: =IF(B19="","",IFERROR(INDEX(Tracker!$D$3:$D$70,MATCH(_xludf.AGGREGATE(15,6,Tracker!$CK$3:$CK$70,10),Tracker!$CK$3:$CK$70,0)),"")) | E19: =IF(B19="","",IFERROR(INDEX(Tracker!$E$3:$E$70,MATCH(_xludf.AGGREGATE(15,6,Tracker!$CK$3:$CK$70,10),Tracker!$CK$3:$CK$70,0)),"")) | F19: =IF(B19="","",IFERROR(INDEX(Tracker!$F$3:$F$70,MATCH(_xludf.AGGREGATE(15,6,Tracker!$CK$3:$CK$70,10),Tracker!$CK$3:$CK$70,0)),"")) | G19: =IF(B19="","",IFERROR(INDEX(Tracker!$G$3:$G$70,MATCH(_xludf.AGGREGATE(15,6,Tracker!$CK$3:$CK$70,10),Tracker!$CK$3:$CK$70,0)),"")) | I19: Dev File R-Task | J19: =SUMPRODUCT((Tracker!$A$3:$A$70<>"")*(Tracker!$AC$3:$AC$70<>"Completed")*(ISNUMBER(Tracker!$AA$3:$AA$70))*(N(Tracker!$AA$3:$AA$70)<TODAY())) | K19: =SUMPRODUCT((Tracker!$A$3:$A$70<>"")*(Tracker!$AC$3:$AC$70<>"Completed")*(ISNUMBER(Tracker!$AA$3:$AA$70))*(N(Tracker!$AA$3:$AA$70)>=TODAY())*(N(Tracker!$AA$3:$AA$70)<=TODAY()+7)) | L19: =SUMPRODUCT((Tracker!$A$3:$A$70<>"")*(ISNUMBER(Tracker!$AA$3:$AA$70))*(Tracker!$AC$3:$AC$70="Blocked")) | M19: =SUMPRODUCT((Tracker!$A$3:$A$70<>"")*(ISNUMBER(Tracker!$AA$3:$AA$70))*(Tracker!$AC$3:$AC$70="In Progress")) | N19: =SUMPRODUCT((Tracker!$A$3:$A$70<>"")*(ISNUMBER(Tracker!$AG$3:$AG$70))*(Tracker!$AH$3:$AH$70<>"Completed")*(Tracker!$AH$3:$AH$70<>"Blocked")*(Tracker!$AH$3:$AH$70<>"In Progress")) | O19: =SUMPRODUCT((Tracker!$A$3:$A$70<>"")*(ISNUMBER(Tracker!$AG$3:$AG$70))*(Tracker!$AH$3:$AH$70="Completed")) | P19: =IF(N(J19)<=0,"",REPT("|",MIN(N(J19),25)))
B20: =IFERROR(INDEX(Tracker!$A$3:$A$70,MATCH(_xludf.AGGREGATE(15,6,Tracker!$CK$3:$CK$70,11),Tracker!$CK$3:$CK$70,0)),"") | C20: =IF(B20="","",IFERROR(INDEX(Tracker!$C$3:$C$70,MATCH(_xludf.AGGREGATE(15,6,Tracker!$CK$3:$CK$70,11),Tracker!$CK$3:$CK$70,0)),"")) | D20: =IF(B20="","",IFERROR(INDEX(Tracker!$D$3:$D$70,MATCH(_xludf.AGGREGATE(15,6,Tracker!$CK$3:$CK$70,11),Tracker!$CK$3:$CK$70,0)),"")) | E20: =IF(B20="","",IFERROR(INDEX(Tracker!$E$3:$E$70,MATCH(_xludf.AGGREGATE(15,6,Tracker!$CK$3:$CK$70,11),Tracker!$CK$3:$CK$70,0)),"")) | F20: =IF(B20="","",IFERROR(INDEX(Tracker!$F$3:$F$70,MATCH(_xludf.AGGREGATE(15,6,Tracker!$CK$3:$CK$70,11),Tracker!$CK$3:$CK$70,0)),"")) | G20: =IF(B20="","",IFERROR(INDEX(Tracker!$G$3:$G$70,MATCH(_xludf.AGGREGATE(15,6,Tracker!$CK$3:$CK$70,11),Tracker!$CK$3:$CK$70,0)),"")) | I20: CAB | J20: =SUMPRODUCT((Tracker!$A$3:$A$70<>"")*(Tracker!$BN$3:$BN$70<>"Completed")*(ISNUMBER(Tracker!$BM$3:$BM$70))*(N(Tracker!$BM$3:$BM$70)<TODAY())) | K20: =SUMPRODUCT((Tracker!$A$3:$A$70<>"")*(Tracker!$BN$3:$BN$70<>"Completed")*(ISNUMBER(Tracker!$BM$3:$BM$70))*(N(Tracker!$BM$3:$BM$70)>=TODAY())*(N(Tracker!$BM$3:$BM$70)<=TODAY()+7)) | L20: =SUMPRODUCT((Tracker!$A$3:$A$70<>"")*(ISNUMBER(Tracker!$BM$3:$BM$70))*(Tracker!$BN$3:$BN$70="Blocked")) | M20: =SUMPRODUCT((Tracker!$A$3:$A$70<>"")*(ISNUMBER(Tracker!$BM$3:$BM$70))*(Tracker!$BN$3:$BN$70="In Progress")) | N20: =SUMPRODUCT((Tracker!$A$3:$A$70<>"")*(ISNUMBER(Tracker!$AE$3:$AE$70))*(Tracker!$AF$3:$AF$70<>"Completed")*(Tracker!$AF$3:$AF$70<>"Blocked")*(Tracker!$AF$3:$AF$70<>"In Progress")) | O20: =SUMPRODUCT((Tracker!$A$3:$A$70<>"")*(ISNUMBER(Tracker!$AE$3:$AE$70))*(Tracker!$AF$3:$AF$70="Completed")) | P20: =IF(N(J20)<=0,"",REPT("|",MIN(N(J20),25)))
B21: =IFERROR(INDEX(Tracker!$A$3:$A$70,MATCH(_xludf.AGGREGATE(15,6,Tracker!$AT$3:$AT$70,12),Tracker!$AT$3:$AT$70,0)),"") | C21: =IF(B21="","",IFERROR(INDEX(Tracker!$B$3:$B$70,MATCH(_xludf.AGGREGATE(15,6,Tracker!$AT$3:$AT$70,12),Tracker!$AT$3:$AT$70,0)),"")) | D21: =IF(B21="","",IFERROR(INDEX(Tracker!$C$3:$C$70,MATCH(_xludf.AGGREGATE(15,6,Tracker!$AT$3:$AT$70,12),Tracker!$AT$3:$AT$70,0)),"")) | E21: =IF(B21="","",IFERROR(INDEX(Tracker!$D$3:$D$70,MATCH(_xludf.AGGREGATE(15,6,Tracker!$AT$3:$AT$70,12),Tracker!$AT$3:$AT$70,0)),"")) | F21: =IF(B21="","",IFERROR(INDEX(Tracker!#REF!,MATCH(_xludf.AGGREGATE(15,6,Tracker!$AT$3:$AT$70,12),Tracker!$AT$3:$AT$70,0)),"")) | G21: =IF(OR(B21="",NOT(ISNUMBER(F21))),"",F21-TODAY()) | I21: Code Review | J21: =SUMPRODUCT((Tracker!$A$3:$A$70<>"")*(Tracker!$BP$3:$BP$70<>"Completed")*(ISNUMBER(Tracker!$BO$3:$BO$70))*(N(Tracker!$BO$3:$BO$70)<TODAY())) | K21: =SUMPRODUCT((Tracker!$A$3:$A$70<>"")*(Tracker!$BP$3:$BP$70<>"Completed")*(ISNUMBER(Tracker!$BO$3:$BO$70))*(N(Tracker!$BO$3:$BO$70)>=TODAY())*(N(Tracker!$BO$3:$BO$70)<=TODAY()+7)) | L21: =SUMPRODUCT((Tracker!$A$3:$A$70<>"")*(ISNUMBER(Tracker!$BO$3:$BO$70))*(Tracker!$BP$3:$BP$70="Blocked")) | M21: =SUMPRODUCT((Tracker!$A$3:$A$70<>"")*(ISNUMBER(Tracker!$BO$3:$BO$70))*(Tracker!$BP$3:$BP$70="In Progress")) | N21: =SUM(N10:N20) | O21: =SUM(O10:O20)

Sheet Tracker
A1: CONTROL STRIP | H1: INPUTS - type dates | K1: AUDIT - Excel fills | N1: READY / READINESS | Q1: DEV DB REQUESTS | Z1: DEV FILE REQUESTS | AG1: QA DB REQUESTS | AP1: QA FILE REQUESTS | AW1: PROD DB REQUESTS | BF1: PROD FILE REQUESTS | BM1: RELEASE GOVERNANCE | BT1: VALIDATION
A2: Application | B2: Responsible PM | C2: Sprint | D2: Overall Status | E2: Next Action | F2: Next Action Date | G2: Days Overdue | H2: Sprint Start | I2: Sprint End | J2: Release Date | K2: Effective Sprint Start | L2: Effective Sprint End | M2: Effective Release Date | N2: App Ready By | O2: Sprint Readiness Date | P2: Sprint Readiness Status | Q2: Dev R-Task | R2: Raised On | S2: Dev R-Task Status | T2: Dev OUR | U2: Raised On | V2: Dev OUR Status | W2: Dev Service Request | X2: Raised On | Y2: Dev SR Status | Z2: File Type | AA2: Dev File R-Task | AB2: Raised On | AC2: Dev File R-Task Status | AD2: IAM | AE2: Ownership Identified | AF2: Frequency | AG2: QA R-Task | AH2: Raised On | AI2: QA R-Task Status | AJ2: QA OUR | AK2: Raised On | AL2: QA OUR Status | AM2: QA Service Request | AN2: Raised On | AO2: QA SR Status | AP2: File Type | AQ2: QA File R-Task | AR2: Raised On | AS2: QA File R-Task Status | AT2: IAM | AU2: Ownership Identified | AV2: Frequency | AW2: Prod R-Task | AX2: Raised On | AY2: Prod R-Task Status | AZ2: Prod OUR | BA2: Raised On | BB2: Prod OUR Status | BC2: Prod Service Request | BD2: Raised On | BE2: Prod SR Status | BF2: File Type | BG2: Prod File R-Task | BH2: Raised On | BI2: Prod File R-Task Status | BJ2: IAM | BK2: Ownership Identified | BL2: Frequency | BM2: CAB Date | BN2: CAB Status | BO2: Code Review Date | BP2: Code Review Status | BQ2: Code Review Invite | BR2: CR Invite Status | BS2: Release Status | BT2: Validation / Notes
A3: ALLOCATIONS | B3: Sharath <Skotha1@randomtrees.com> | C3: Sprint 17 | D3: =IF(A8="","",IF(((S8="Blocked")+(V8="Blocked")+(Y8="Blocked")+(AC8="Blocked")+(AI8="Blocked")+(AL8="Blocked")+(AO8="Blocked")+(AS8="Blocked")+(AY8="Blocked")+(BB8="Blocked")+(BE8="Blocked")+(BI8="Blocked")+(P8="Blocked")+(BN8="Blocked")+(BP8="Blocked")+(BR8="Blocked")+(BS8="Blocked"))>0,"Blocked",IF((ISNUMBER(Q8)+ISNUMBER(T8)+ISNUMBER(W8)+ISNUMBER(AA8)+ISNUMBER(AG8)+ISNUMBER(AJ8)+ISNUMBER(AM8)+ISNUMBER(AQ8)+ISNUMBER(AW8)+ISNUMBER(AZ8)+ISNUMBER(BC8)+ISNUMBER(BG8)+ISNUMBER(O8)+ISNUMBER(BM8)+ISNUMBER(BO8)+ISNUMBER(BQ8))=0,"Yet to start",IF(AND(OR(NOT(ISNUMBER(Q8)),S8="Completed"),OR(NOT(ISNUMBER(T8)),V8="Completed"),OR(NOT(ISNUMBER(W8)),Y8="Completed"),OR(NOT(ISNUMBER(AA8)),AC8="Completed"),OR(NOT(ISNUMBER(AG8)),AI8="Completed"),OR(NOT(ISNUMBER(AJ8)),AL8="Completed"),OR(NOT(ISNUMBER(AM8)),AO8="Completed"),OR(NOT(ISNUMBER(AQ8)),AS8="Completed"),OR(NOT(ISNUMBER(AW8)),AY8="Completed"),OR(NOT(ISNUMBER(AZ8)),BB8="Completed"),OR(NOT(ISNUMBER(BC8)),BE8="Completed"),OR(NOT(ISNUMBER(BG8)),BI8="Completed"),OR(NOT(ISNUMBER(O8)),P8="Completed"),OR(NOT(ISNUMBER(BM8)),BN8="Completed"),OR(NOT(ISNUMBER(BO8)),BP8="Completed"),OR(NOT(ISNUMBER(BQ8)),BR8="Completed"),BS8="Completed"),"Completed",IF(((S8="In Progress")+(V8="In Progress")+(Y8="In Progress")+(AC8="In Progress")+(AI8="In Progress")+(AL8="In Progress")+(AO8="In Progress")+(AS8="In Progress")+(AY8="In Progress")+(BB8="In Progress")+(BE8="In Progress")+(BI8="In Progress")+(P8="In Progress")+(BN8="In Progress")+(BP8="In Progress")+(BR8="In Progress")+(BS8="In Progress"))>0,"In Progress","Yet to start"))))) | E3: =IF(A3="","",IF(F3="","All complete",INDEX({"Dev R-Task","Dev OUR","Dev Service Request","Dev File R-Task","QA R-Task","QA OUR","QA Service Request","QA File R-Task","Prod R-Task","Prod OUR","Prod Service Request","Prod File R-Task","Sprint Readiness","Code Review Invite","Code Review","CAB"},MATCH(F3,BU3:CJ3,0)))) | F3: =IF(A3="","",IF(COUNT(BU3:CJ3)=0,"",MIN(BU3:CJ3))) | G3: =IF(A3="","",MAX(0,IF(AND(ISNUMBER(Q3),S3<>"Completed",Q3<TODAY()),TODAY()-Q3,0),IF(AND(ISNUMBER(T3),V3<>"Completed",T3<TODAY()),TODAY()-T3,0),IF(AND(ISNUMBER(W3),Y3<>"Completed",W3<TODAY()),TODAY()-W3,0),IF(AND(ISNUMBER(AA3),AC3<>"Completed",AA3<TODAY()),TODAY()-AA3,0),IF(AND(ISNUMBER(AG3),AI3<>"Completed",AG3<TODAY()),TODAY()-AG3,0),IF(AND(ISNUMBER(AJ3),AL3<>"Completed",AJ3<TODAY()),TODAY()-AJ3,0),IF(AND(ISNUMBER(AM3),AO3<>"Completed",AM3<TODAY()),TODAY()-AM3,0),IF(AND(ISNUMBER(AQ3),AS3<>"Completed",AQ3<TODAY()),TODAY()-AQ3,0),IF(AND(ISNUMBER(AW3),AY3<>"Completed",AW3<TODAY()),TODAY()-AW3,0),IF(AND(ISNUMBER(AZ3),BB3<>"Completed",AZ3<TODAY()),TODAY()-AZ3,0),IF(AND(ISNUMBER(BC3),BE3<>"Completed",BC3<TODAY()),TODAY()-BC3,0),IF(AND(ISNUMBER(BG3),BI3<>"Completed",BG3<TODAY()),TODAY()-BG3,0),IF(AND(ISNUMBER(O3),P3<>"Completed",O3<TODAY()),TODAY()-O3,0),IF(AND(ISNUMBER(BQ3),BR3<>"Completed",BQ3<TODAY()),TODAY()-BQ3,0),IF(AND(ISNUMBER(BO3),BP3<>"Completed",BO3<TODAY()),TODAY()-BO3,0),IF(AND(ISNUMBER(BM3),BN3<>"Completed",BM3<TODAY()),TODAY()-BM3,0))) | H3: 46232 | I3: 46245 | J3: 46276 | K3: =IF(ISNUMBER(H3),H3,IF(ISNUMBER(M3),M3-WEEKDAY(M3,2)+1-7,"")) | L3: =IF(ISNUMBER(I3),I3,IF(ISNUMBER(H3),WORKDAY(H3,SprintWorkingDays-1),IF(ISNUMBER(K3),WORKDAY(K3,SprintWorkingDays-1),""))) | M3: =IF(ISNUMBER(J3),J3,IF(ISNUMBER(I3),I3-IF(OR(WEEKDAY(I3,2)=2,WEEKDAY(I3,2)=4),0,IF(WEEKDAY(I3,2)=3,1,IF(WEEKDAY(I3,2)=1,4,WEEKDAY(I3,2)-4))),IF(ISNUMBER(H3),WORKDAY(H3,SprintWorkingDays-1)-IF(OR(WEEKDAY(WORKDAY(H3,SprintWorkingDays-1),2)=2,WEEKDAY(WORKDAY(H3,SprintWorkingDays-1),2)=4),0,IF(WEEKDAY(WORKDAY(H3,SprintWorkingDays-1),2)=3,1,IF(WEEKDAY(WORKDAY(H3,SprintWorkingDays-1),2)=1,4,WEEKDAY(WORKDAY(H3,SprintWorkingDays-1),2)-4))),""))) | N3: =IF(NOT(ISNUMBER(K3)),"",WORKDAY(K3,ReadyOffsetWD)) | O3: =IF(NOT(ISNUMBER(K3)),"",WORKDAY(K3,SprintReadinessOffsetWD)) | Q3: =IF(NOT(ISNUMBER(T3)),"",WORKDAY(T3,RTSKOffsetFromOUR_WD)) | S3: Completed | T3: =IF(NOT(ISNUMBER(W3)),"",WORKDAY(W3,OUROffsetFromSR_WD)) | W3: =IF(NOT(ISNUMBER(K3)),"",WORKDAY(K3,SROffsetFromStartWD)) | AA3: =IF(ISNUMBER(Q3),Q3,"") | AG3: =IF(NOT(ISNUMBER(Q3)),"",Q3) | AJ3: =IF(NOT(ISNUMBER(T3)),"",T3) | AM3: =IF(NOT(ISNUMBER(W3)),"",W3) | AQ3: =IF(ISNUMBER(AG3),AG3,"") | AW3: =IF(NOT(ISNUMBER(Q3)),"",Q3) | AZ3: =IF(NOT(ISNUMBER(T3)),"",T3) | BC3: =IF(NOT(ISNUMBER(W3)),"",W3) | BG3: =IF(ISNUMBER(AW3),AW3,"") | BM3: 46213 | BO3: =IF(NOT(ISNUMBER(BM3)),"",IF(WEEKDAY(BM3-CodeReviewCalendarDays,2)>5,BM3-CodeReviewCalendarDays-(WEEKDAY(BM3-CodeReviewCalendarDays,2)-5),BM3-CodeReviewCalendarDays)) | BQ3: =IF(NOT(ISNUMBER(BO3)),"",IF(WEEKDAY(BO3-CodeReviewInviteCalendarDays,2)>5,BO3-CodeReviewInviteCalendarDays-(WEEKDAY(BO3-CodeReviewInviteCalendarDays,2)-5),BO3-CodeReviewInviteCalendarDays)) | BT3: =IF(A3="","",IF(IF(AND(ISNUMBER(J3),WEEKDAY(J3,2)<>2,WEEKDAY(J3,2)<>4)," | Release must be Tuesday or Thursday","")&IF(AND(ISNUMBER(H3),WEEKDAY(H3,2)<>1)," | Sprint Start is not a Monday - dates still calculated from the date entered","")&IF(AND(A3<>"",NOT(ISNUMBER(H3)),NOT(ISNUMBER(J3)))," | Enter Sprint Start or Release Date","")&IF(AND(ISNUMBER(F3),F3<TODAY(),D3<>"Completed")," | One or more raise-by dates are in the past and not completed","")&IF(AND(ISNUMBER(K3),K3-TODAY()<SprintWarningDays,K3>=TODAY(),OR(D3="Yet to start",D3="Blocked"))," | Sprint starts in under 10 days - raise access requests now","")&IF(AND(ISNUMBER(BQ3),BR3<>"Completed",BQ3-TODAY()<CodeReviewInviteCalendarDays)," | Code Review invite should be sent at least 4 days before Code Review","")="","",MID(IF(AND(ISNUMBER(J3),WEEKDAY(J3,2)<>2,WEEKDAY(J3,2)<>4)," | Release must be Tuesday or Thursday","")&IF(AND(ISNUMBER(H3),WEEKDAY(H3,2)<>1)," | Sprint Start is not a Monday - dates still calculated from the date entered","")&IF(AND(A3<>"",NOT(ISNUMBER(H3)),NOT(ISNUMBER(J3)))," | Enter Sprint Start or Release Date","")&IF(AND(ISNUMBER(F3),F3<TODAY(),D3<>"Completed")," | One or more raise-by dates are in the past and not completed","")&IF(AND(ISNUMBER(K3),K3-TODAY()<SprintWarningDays,K3>=TODAY(),OR(D3="Yet to start",D3="Blocked"))," | Sprint starts in under 10 days - raise access requests now","")&IF(AND(ISNUMBER(BQ3),BR3<>"Completed",BQ3-TODAY()<CodeReviewInviteCalendarDays)," | Code Review invite should be sent at least 4 days before Code Review",""),4,500))) | BU3: =IF(AND(ISNUMBER(Q3),S3<>"Completed"),Q3,"") | BV3: =IF(AND(ISNUMBER(T3),V3<>"Completed"),T3,"") | BW3: =IF(AND(ISNUMBER(W3),Y3<>"Completed"),W3,"") | BX3: =IF(AND(ISNUMBER(AA3),AC3<>"Completed"),AA3,"") | BY3: =IF(AND(ISNUMBER(AG3),AI3<>"Completed"),AG3,"") | BZ3: =IF(AND(ISNUMBER(AJ3),AL3<>"Completed"),AJ3,"") | CA3: =IF(AND(ISNUMBER(AM3),AO3<>"Completed"),AM3,"") | CB3: =IF(AND(ISNUMBER(AQ3),AS3<>"Completed"),AQ3,"") | CC3: =IF(AND(ISNUMBER(AW3),AY3<>"Completed"),AW3,"") | CD3: =IF(AND(ISNUMBER(AZ3),BB3<>"Completed"),AZ3,"") | CE3: =IF(AND(ISNUMBER(BC3),BE3<>"Completed"),BC3,"") | CF3: =IF(AND(ISNUMBER(BG3),BI3<>"Completed"),BG3,"") | CG3: =IF(AND(ISNUMBER(O3),P3<>"Completed"),O3,"") | CH3: =IF(AND(ISNUMBER(BQ3),BR3<>"Completed"),BQ3,"") | CI3: =IF(AND(ISNUMBER(BO3),BP3<>"Completed"),BO3,"") | CJ3: =IF(AND(ISNUMBER(BM3),BN3<>"Completed"),BM3,"") | CK3: =IF(OR(A3="",D3="Completed"),"",IF(N(G3)>0,1/(N(G3)+ROW()/100000),IF(ISNUMBER(F3),1000+F3+ROW()/100000,TODAY()+400+ROW()/100000)))
A4: AR80 | B4: Santhosh <skoyalkar@randomtrees.com> | C4: Sprint 17 | D4: =IF(A7="","",IF(((S7="Blocked")+(V7="Blocked")+(Y7="Blocked")+(AC7="Blocked")+(AI7="Blocked")+(AL7="Blocked")+(AO7="Blocked")+(AS7="Blocked")+(AY7="Blocked")+(BB7="Blocked")+(BE7="Blocked")+(BI7="Blocked")+(P7="Blocked")+(BN7="Blocked")+(BP7="Blocked")+(BR7="Blocked")+(BS7="Blocked"))>0,"Blocked",IF((ISNUMBER(Q7)+ISNUMBER(T7)+ISNUMBER(W7)+ISNUMBER(AA7)+ISNUMBER(AG7)+ISNUMBER(AJ7)+ISNUMBER(AM7)+ISNUMBER(AQ7)+ISNUMBER(AW7)+ISNUMBER(AZ7)+ISNUMBER(BC7)+ISNUMBER(BG7)+ISNUMBER(O7)+ISNUMBER(BM7)+ISNUMBER(BO7)+ISNUMBER(BQ7))=0,"Yet to start",IF(AND(OR(NOT(ISNUMBER(Q7)),S7="Completed"),OR(NOT(ISNUMBER(T7)),V7="Completed"),OR(NOT(ISNUMBER(W7)),Y7="Completed"),OR(NOT(ISNUMBER(AA7)),AC7="Completed"),OR(NOT(ISNUMBER(AG7)),AI7="Completed"),OR(NOT(ISNUMBER(AJ7)),AL7="Completed"),OR(NOT(ISNUMBER(AM7)),AO7="Completed"),OR(NOT(ISNUMBER(AQ7)),AS7="Completed"),OR(NOT(ISNUMBER(AW7)),AY7="Completed"),OR(NOT(ISNUMBER(AZ7)),BB7="Completed"),OR(NOT(ISNUMBER(BC7)),BE7="Completed"),OR(NOT(ISNUMBER(BG7)),BI7="Completed"),OR(NOT(ISNUMBER(O7)),P7="Completed"),OR(NOT(ISNUMBER(BM7)),BN7="Completed"),OR(NOT(ISNUMBER(BO7)),BP7="Completed"),OR(NOT(ISNUMBER(BQ7)),BR7="Completed"),BS7="Completed"),"Completed",IF(((S7="In Progress")+(V7="In Progress")+(Y7="In Progress")+(AC7="In Progress")+(AI7="In Progress")+(AL7="In Progress")+(AO7="In Progress")+(AS7="In Progress")+(AY7="In Progress")+(BB7="In Progress")+(BE7="In Progress")+(BI7="In Progress")+(P7="In Progress")+(BN7="In Progress")+(BP7="In Progress")+(BR7="In Progress")+(BS7="In Progress"))>0,"In Progress","Yet to start"))))) | E4: =IF(A4="","",IF(F4="","All complete",INDEX({"Dev R-Task","Dev OUR","Dev Service Request","Dev File R-Task","QA R-Task","QA OUR","QA Service Request","QA File R-Task","Prod R-Task","Prod OUR","Prod Service Request","Prod File R-Task","Sprint Readiness","Code Review Invite","Code Review","CAB"},MATCH(F4,BU4:CJ4,0)))) | F4: =IF(A4="","",IF(COUNT(BU4:CJ4)=0,"",MIN(BU4:CJ4))) | G4: =IF(A4="","",MAX(0,IF(AND(ISNUMBER(Q4),S4<>"Completed",Q4<TODAY()),TODAY()-Q4,0),IF(AND(ISNUMBER(T4),V4<>"Completed",T4<TODAY()),TODAY()-T4,0),IF(AND(ISNUMBER(W4),Y4<>"Completed",W4<TODAY()),TODAY()-W4,0),IF(AND(ISNUMBER(AA4),AC4<>"Completed",AA4<TODAY()),TODAY()-AA4,0),IF(AND(ISNUMBER(AG4),AI4<>"Completed",AG4<TODAY()),TODAY()-AG4,0),IF(AND(ISNUMBER(AJ4),AL4<>"Completed",AJ4<TODAY()),TODAY()-AJ4,0),IF(AND(ISNUMBER(AM4),AO4<>"Completed",AM4<TODAY()),TODAY()-AM4,0),IF(AND(ISNUMBER(AQ4),AS4<>"Completed",AQ4<TODAY()),TODAY()-AQ4,0),IF(AND(ISNUMBER(AW4),AY4<>"Completed",AW4<TODAY()),TODAY()-AW4,0),IF(AND(ISNUMBER(AZ4),BB4<>"Completed",AZ4<TODAY()),TODAY()-AZ4,0),IF(AND(ISNUMBER(BC4),BE4<>"Completed",BC4<TODAY()),TODAY()-BC4,0),IF(AND(ISNUMBER(BG4),BI4<>"Completed",BG4<TODAY()),TODAY()-BG4,0),IF(AND(ISNUMBER(O4),P4<>"Completed",O4<TODAY()),TODAY()-O4,0),IF(AND(ISNUMBER(BQ4),BR4<>"Completed",BQ4<TODAY()),TODAY()-BQ4,0),IF(AND(ISNUMBER(BO4),BP4<>"Completed",BO4<TODAY()),TODAY()-BO4,0),IF(AND(ISNUMBER(BM4),BN4<>"Completed",BM4<TODAY()),TODAY()-BM4,0))) | H4: 46232 | I4: 46245 | J4: 46276 | K4: =IF(ISNUMBER(H4),H4,IF(ISNUMBER(M4),M4-WEEKDAY(M4,2)+1-7,"")) | L4: =IF(ISNUMBER(I4),I4,IF(ISNUMBER(H4),WORKDAY(H4,SprintWorkingDays-1),IF(ISNUMBER(K4),WORKDAY(K4,SprintWorkingDays-1),""))) | M4: =IF(ISNUMBER(J4),J4,IF(ISNUMBER(I4),I4-IF(OR(WEEKDAY(I4,2)=2,WEEKDAY(I4,2)=4),0,IF(WEEKDAY(I4,2)=3,1,IF(WEEKDAY(I4,2)=1,4,WEEKDAY(I4,2)-4))),IF(ISNUMBER(H4),WORKDAY(H4,SprintWorkingDays-1)-IF(OR(WEEKDAY(WORKDAY(H4,SprintWorkingDays-1),2)=2,WEEKDAY(WORKDAY(H4,SprintWorkingDays-1),2)=4),0,IF(WEEKDAY(WORKDAY(H4,SprintWorkingDays-1),2)=3,1,IF(WEEKDAY(WORKDAY(H4,SprintWorkingDays-1),2)=1,4,WEEKDAY(WORKDAY(H4,SprintWorkingDays-1),2)-4))),""))) | N4: =IF(NOT(ISNUMBER(K4)),"",WORKDAY(K4,ReadyOffsetWD)) | O4: =IF(NOT(ISNUMBER(K4)),"",WORKDAY(K4,SprintReadinessOffsetWD)) | Q4: =IF(NOT(ISNUMBER(T4)),"",WORKDAY(T4,RTSKOffsetFromOUR_WD)) | S4: Yet to start | T4: =IF(NOT(ISNUMBER(W4)),"",WORKDAY(W4,OUROffsetFromSR_WD)) | W4: =IF(NOT(ISNUMBER(K4)),"",WORKDAY(K4,SROffsetFromStartWD)) | AA4: =IF(ISNUMBER(Q4),Q4,"") | AG4: =IF(NOT(ISNUMBER(Q4)),"",Q4) | AJ4: =IF(NOT(ISNUMBER(T4)),"",T4) | AM4: =IF(NOT(ISNUMBER(W4)),"",W4) | AQ4: =IF(ISNUMBER(AG4),AG4,"") | AW4: =IF(NOT(ISNUMBER(Q4)),"",Q4) | AZ4: =IF(NOT(ISNUMBER(T4)),"",T4) | BC4: =IF(NOT(ISNUMBER(W4)),"",W4) | BG4: =IF(ISNUMBER(AW4),AW4,"") | BM4: 46213 | BO4: =IF(NOT(ISNUMBER(BM4)),"",IF(WEEKDAY(BM4-CodeReviewCalendarDays,2)>5,BM4-CodeReviewCalendarDays-(WEEKDAY(BM4-CodeReviewCalendarDays,2)-5),BM4-CodeReviewCalendarDays)) | BQ4: =IF(NOT(ISNUMBER(BO4)),"",IF(WEEKDAY(BO4-CodeReviewInviteCalendarDays,2)>5,BO4-CodeReviewInviteCalendarDays-(WEEKDAY(BO4-CodeReviewInviteCalendarDays,2)-5),BO4-CodeReviewInviteCalendarDays)) | BT4: =IF(A4="","",IF(IF(AND(ISNUMBER(J4),WEEKDAY(J4,2)<>2,WEEKDAY(J4,2)<>4)," | Release must be Tuesday or Thursday","")&IF(AND(ISNUMBER(H4),WEEKDAY(H4,2)<>1)," | Sprint Start is not a Monday - dates still calculated from the date entered","")&IF(AND(A4<>"",NOT(ISNUMBER(H4)),NOT(ISNUMBER(J4)))," | Enter Sprint Start or Release Date","")&IF(AND(ISNUMBER(F4),F4<TODAY(),D4<>"Completed")," | One or more raise-by dates are in the past and not completed","")&IF(AND(ISNUMBER(K4),K4-TODAY()<SprintWarningDays,K4>=TODAY(),OR(D4="Yet to start",D4="Blocked"))," | Sprint starts in under 10 days - raise access requests now","")&IF(AND(ISNUMBER(BQ4),BR4<>"Completed",BQ4-TODAY()<CodeReviewInviteCalendarDays)," | Code Review invite should be sent at least 4 days before Code Review","")="","",MID(IF(AND(ISNUMBER(J4),WEEKDAY(J4,2)<>2,WEEKDAY(J4,2)<>4)," | Release must be Tuesday or Thursday","")&IF(AND(ISNUMBER(H4),WEEKDAY(H4,2)<>1)," | Sprint Start is not a Monday - dates still calculated from the date entered","")&IF(AND(A4<>"",NOT(ISNUMBER(H4)),NOT(ISNUMBER(J4)))," | Enter Sprint Start or Release Date","")&IF(AND(ISNUMBER(F4),F4<TODAY(),D4<>"Completed")," | One or more raise-by dates are in the past and not completed","")&IF(AND(ISNUMBER(K4),K4-TODAY()<SprintWarningDays,K4>=TODAY(),OR(D4="Yet to start",D4="Blocked"))," | Sprint starts in under 10 days - raise access requests now","")&IF(AND(ISNUMBER(BQ4),BR4<>"Completed",BQ4-TODAY()<CodeReviewInviteCalendarDays)," | Code Review invite should be sent at least 4 days before Code Review",""),4,500))) | BU4: =IF(AND(ISNUMBER(Q4),S4<>"Completed"),Q4,"") | BV4: =IF(AND(ISNUMBER(T4),V4<>"Completed"),T4,"") | BW4: =IF(AND(ISNUMBER(W4),Y4<>"Completed"),W4,"") | BX4: =IF(AND(ISNUMBER(AA4),AC4<>"Completed"),AA4,"") | BY4: =IF(AND(ISNUMBER(AG4),AI4<>"Completed"),AG4,"") | BZ4: =IF(AND(ISNUMBER(AJ4),AL4<>"Completed"),AJ4,"") | CA4: =IF(AND(ISNUMBER(AM4),AO4<>"Completed"),AM4,"") | CB4: =IF(AND(ISNUMBER(AQ4),AS4<>"Completed"),AQ4,"") | CC4: =IF(AND(ISNUMBER(AW4),AY4<>"Completed"),AW4,"") | CD4: =IF(AND(ISNUMBER(AZ4),BB4<>"Completed"),AZ4,"") | CE4: =IF(AND(ISNUMBER(BC4),BE4<>"Completed"),BC4,"") | CF4: =IF(AND(ISNUMBER(BG4),BI4<>"Completed"),BG4,"") | CG4: =IF(AND(ISNUMBER(O4),P4<>"Completed"),O4,"") | CH4: =IF(AND(ISNUMBER(BQ4),BR4<>"Completed"),BQ4,"") | CI4: =IF(AND(ISNUMBER(BO4),BP4<>"Completed"),BO4,"") | CJ4: =IF(AND(ISNUMBER(BM4),BN4<>"Completed"),BM4,"") | CK4: =IF(OR(A4="",D4="Completed"),"",IF(N(G4)>0,1/(N(G4)+ROW()/100000),IF(ISNUMBER(F4),1000+F4+ROW()/100000,TODAY()+400+ROW()/100000)))
A5: BI80 | B5: Sandeep <sgodi@randomtrees.com> | C5: Sprint 17 | D5: =IF(A6="","",IF(((S6="Blocked")+(V6="Blocked")+(Y6="Blocked")+(AC6="Blocked")+(AI6="Blocked")+(AL6="Blocked")+(AO6="Blocked")+(AS6="Blocked")+(AY6="Blocked")+(BB6="Blocked")+(BE6="Blocked")+(BI6="Blocked")+(P6="Blocked")+(BN6="Blocked")+(BP6="Blocked")+(BR6="Blocked")+(BS6="Blocked"))>0,"Blocked",IF((ISNUMBER(Q6)+ISNUMBER(T6)+ISNUMBER(W6)+ISNUMBER(AA6)+ISNUMBER(AG6)+ISNUMBER(AJ6)+ISNUMBER(AM6)+ISNUMBER(AQ6)+ISNUMBER(AW6)+ISNUMBER(AZ6)+ISNUMBER(BC6)+ISNUMBER(BG6)+ISNUMBER(O6)+ISNUMBER(BM6)+ISNUMBER(BO6)+ISNUMBER(BQ6))=0,"Yet to start",IF(AND(OR(NOT(ISNUMBER(Q6)),S6="Completed"),OR(NOT(ISNUMBER(T6)),V6="Completed"),OR(NOT(ISNUMBER(W6)),Y6="Completed"),OR(NOT(ISNUMBER(AA6)),AC6="Completed"),OR(NOT(ISNUMBER(AG6)),AI6="Completed"),OR(NOT(ISNUMBER(AJ6)),AL6="Completed"),OR(NOT(ISNUMBER(AM6)),AO6="Completed"),OR(NOT(ISNUMBER(AQ6)),AS6="Completed"),OR(NOT(ISNUMBER(AW6)),AY6="Completed"),OR(NOT(ISNUMBER(AZ6)),BB6="Completed"),OR(NOT(ISNUMBER(BC6)),BE6="Completed"),OR(NOT(ISNUMBER(BG6)),BI6="Completed"),OR(NOT(ISNUMBER(O6)),P6="Completed"),OR(NOT(ISNUMBER(BM6)),BN6="Completed"),OR(NOT(ISNUMBER(BO6)),BP6="Completed"),OR(NOT(ISNUMBER(BQ6)),BR6="Completed"),BS6="Completed"),"Completed",IF(((S6="In Progress")+(V6="In Progress")+(Y6="In Progress")+(AC6="In Progress")+(AI6="In Progress")+(AL6="In Progress")+(AO6="In Progress")+(AS6="In Progress")+(AY6="In Progress")+(BB6="In Progress")+(BE6="In Progress")+(BI6="In Progress")+(P6="In Progress")+(BN6="In Progress")+(BP6="In Progress")+(BR6="In Progress")+(BS6="In Progress"))>0,"In Progress","Yet to start"))))) | E5: =IF(A5="","",IF(F5="","All complete",INDEX({"Dev R-Task","Dev OUR","Dev Service Request","Dev File R-Task","QA R-Task","QA OUR","QA Service Request","QA File R-Task","Prod R-Task","Prod OUR","Prod Service Request","Prod File R-Task","Sprint Readiness","Code Review Invite","Code Review","CAB"},MATCH(F5,BU5:CJ5,0)))) | F5: =IF(A5="","",IF(COUNT(BU5:CJ5)=0,"",MIN(BU5:CJ5))) | G5: =IF(A5="","",MAX(0,IF(AND(ISNUMBER(Q5),S5<>"Completed",Q5<TODAY()),TODAY()-Q5,0),IF(AND(ISNUMBER(T5),V5<>"Completed",T5<TODAY()),TODAY()-T5,0),IF(AND(ISNUMBER(W5),Y5<>"Completed",W5<TODAY()),TODAY()-W5,0),IF(AND(ISNUMBER(AA5),AC5<>"Completed",AA5<TODAY()),TODAY()-AA5,0),IF(AND(ISNUMBER(AG5),AI5<>"Completed",AG5<TODAY()),TODAY()-AG5,0),IF(AND(ISNUMBER(AJ5),AL5<>"Completed",AJ5<TODAY()),TODAY()-AJ5,0),IF(AND(ISNUMBER(AM5),AO5<>"Completed",AM5<TODAY()),TODAY()-AM5,0),IF(AND(ISNUMBER(AQ5),AS5<>"Completed",AQ5<TODAY()),TODAY()-AQ5,0),IF(AND(ISNUMBER(AW5),AY5<>"Completed",AW5<TODAY()),TODAY()-AW5,0),IF(AND(ISNUMBER(AZ5),BB5<>"Completed",AZ5<TODAY()),TODAY()-AZ5,0),IF(AND(ISNUMBER(BC5),BE5<>"Completed",BC5<TODAY()),TODAY()-BC5,0),IF(AND(ISNUMBER(BG5),BI5<>"Completed",BG5<TODAY()),TODAY()-BG5,0),IF(AND(ISNUMBER(O5),P5<>"Completed",O5<TODAY()),TODAY()-O5,0),IF(AND(ISNUMBER(BQ5),BR5<>"Completed",BQ5<TODAY()),TODAY()-BQ5,0),IF(AND(ISNUMBER(BO5),BP5<>"Completed",BO5<TODAY()),TODAY()-BO5,0),IF(AND(ISNUMBER(BM5),BN5<>"Completed",BM5<TODAY()),TODAY()-BM5,0))) | H5: 46232 | I5: 46245 | J5: 46276 | K5: =IF(ISNUMBER(H5),H5,IF(ISNUMBER(M5),M5-WEEKDAY(M5,2)+1-7,"")) | L5: =IF(ISNUMBER(I5),I5,IF(ISNUMBER(H5),WORKDAY(H5,SprintWorkingDays-1),IF(ISNUMBER(K5),WORKDAY(K5,SprintWorkingDays-1),""))) | M5: =IF(ISNUMBER(J5),J5,IF(ISNUMBER(I5),I5-IF(OR(WEEKDAY(I5,2)=2,WEEKDAY(I5,2)=4),0,IF(WEEKDAY(I5,2)=3,1,IF(WEEKDAY(I5,2)=1,4,WEEKDAY(I5,2)-4))),IF(ISNUMBER(H5),WORKDAY(H5,SprintWorkingDays-1)-IF(OR(WEEKDAY(WORKDAY(H5,SprintWorkingDays-1),2)=2,WEEKDAY(WORKDAY(H5,SprintWorkingDays-1),2)=4),0,IF(WEEKDAY(WORKDAY(H5,SprintWorkingDays-1),2)=3,1,IF(WEEKDAY(WORKDAY(H5,SprintWorkingDays-1),2)=1,4,WEEKDAY(WORKDAY(H5,SprintWorkingDays-1),2)-4))),""))) | N5: =IF(NOT(ISNUMBER(K5)),"",WORKDAY(K5,ReadyOffsetWD)) | O5: =IF(NOT(ISNUMBER(K5)),"",WORKDAY(K5,SprintReadinessOffsetWD)) | Q5: =IF(NOT(ISNUMBER(T5)),"",WORKDAY(T5,RTSKOffsetFromOUR_WD)) | T5: =IF(NOT(ISNUMBER(W5)),"",WORKDAY(W5,OUROffsetFromSR_WD)) | W5: =IF(NOT(ISNUMBER(K5)),"",WORKDAY(K5,SROffsetFromStartWD)) | AA5: =IF(ISNUMBER(Q5),Q5,"") | AG5: =IF(NOT(ISNUMBER(Q5)),"",Q5) | AJ5: =IF(NOT(ISNUMBER(T5)),"",T5) | AM5: =IF(NOT(ISNUMBER(W5)),"",W5) | AQ5: =IF(ISNUMBER(AG5),AG5,"") | AW5: =IF(NOT(ISNUMBER(Q5)),"",Q5) | AZ5: =IF(NOT(ISNUMBER(T5)),"",T5) | BC5: =IF(NOT(ISNUMBER(W5)),"",W5) | BG5: =IF(ISNUMBER(AW5),AW5,"") | BM5: 46213 | BO5: =IF(NOT(ISNUMBER(BM5)),"",IF(WEEKDAY(BM5-CodeReviewCalendarDays,2)>5,BM5-CodeReviewCalendarDays-(WEEKDAY(BM5-CodeReviewCalendarDays,2)-5),BM5-CodeReviewCalendarDays)) | BQ5: =IF(NOT(ISNUMBER(BO5)),"",IF(WEEKDAY(BO5-CodeReviewInviteCalendarDays,2)>5,BO5-CodeReviewInviteCalendarDays-(WEEKDAY(BO5-CodeReviewInviteCalendarDays,2)-5),BO5-CodeReviewInviteCalendarDays)) | BT5: =IF(A5="","",IF(IF(AND(ISNUMBER(J5),WEEKDAY(J5,2)<>2,WEEKDAY(J5,2)<>4)," | Release must be Tuesday or Thursday","")&IF(AND(ISNUMBER(H5),WEEKDAY(H5,2)<>1)," | Sprint Start is not a Monday - dates still calculated from the date entered","")&IF(AND(A5<>"",NOT(ISNUMBER(H5)),NOT(ISNUMBER(J5)))," | Enter Sprint Start or Release Date","")&IF(AND(ISNUMBER(F5),F5<TODAY(),D5<>"Completed")," | One or more raise-by dates are in the past and not completed","")&IF(AND(ISNUMBER(K5),K5-TODAY()<SprintWarningDays,K5>=TODAY(),OR(D5="Yet to start",D5="Blocked"))," | Sprint starts in under 10 days - raise access requests now","")&IF(AND(ISNUMBER(BQ5),BR5<>"Completed",BQ5-TODAY()<CodeReviewInviteCalendarDays)," | Code Review invite should be sent at least 4 days before Code Review","")="","",MID(IF(AND(ISNUMBER(J5),WEEKDAY(J5,2)<>2,WEEKDAY(J5,2)<>4)," | Release must be Tuesday or Thursday","")&IF(AND(ISNUMBER(H5),WEEKDAY(H5,2)<>1)," | Sprint Start is not a Monday - dates still calculated from the date entered","")&IF(AND(A5<>"",NOT(ISNUMBER(H5)),NOT(ISNUMBER(J5)))," | Enter Sprint Start or Release Date","")&IF(AND(ISNUMBER(F5),F5<TODAY(),D5<>"Completed")," | One or more raise-by dates are in the past and not completed","")&IF(AND(ISNUMBER(K5),K5-TODAY()<SprintWarningDays,K5>=TODAY(),OR(D5="Yet to start",D5="Blocked"))," | Sprint starts in under 10 days - raise access requests now","")&IF(AND(ISNUMBER(BQ5),BR5<>"Completed",BQ5-TODAY()<CodeReviewInviteCalendarDays)," | Code Review invite should be sent at least 4 days before Code Review",""),4,500))) | BU5: =IF(AND(ISNUMBER(Q5),S5<>"Completed"),Q5,"") | BV5: =IF(AND(ISNUMBER(T5),V5<>"Completed"),T5,"") | BW5: =IF(AND(ISNUMBER(W5),Y5<>"Completed"),W5,"") | BX5: =IF(AND(ISNUMBER(AA5),AC5<>"Completed"),AA5,"") | BY5: =IF(AND(ISNUMBER(AG5),AI5<>"Completed"),AG5,"") | BZ5: =IF(AND(ISNUMBER(AJ5),AL5<>"Completed"),AJ5,"") | CA5: =IF(AND(ISNUMBER(AM5),AO5<>"Completed"),AM5,"") | CB5: =IF(AND(ISNUMBER(AQ5),AS5<>"Completed"),AQ5,"") | CC5: =IF(AND(ISNUMBER(AW5),AY5<>"Completed"),AW5,"") | CD5: =IF(AND(ISNUMBER(AZ5),BB5<>"Completed"),AZ5,"") | CE5: =IF(AND(ISNUMBER(BC5),BE5<>"Completed"),BC5,"") | CF5: =IF(AND(ISNUMBER(BG5),BI5<>"Completed"),BG5,"") | CG5: =IF(AND(ISNUMBER(O5),P5<>"Completed"),O5,"") | CH5: =IF(AND(ISNUMBER(BQ5),BR5<>"Completed"),BQ5,"") | CI5: =IF(AND(ISNUMBER(BO5),BP5<>"Completed"),BO5,"") | CJ5: =IF(AND(ISNUMBER(BM5),BN5<>"Completed"),BM5,"") | CK5: =IF(OR(A5="",D5="Completed"),"",IF(N(G5)>0,1/(N(G5)+ROW()/100000),IF(ISNUMBER(F5),1000+F5+ROW()/100000,TODAY()+400+ROW()/100000)))
